[Thu Apr 11 07:11:59.063196 2019] [wsgi:warn] [pid 17741:tid 139660859996032] mod_wsgi: Compiled for Python/3.5.1+.
[Thu Apr 11 07:11:59.063279 2019] [wsgi:warn] [pid 17741:tid 139660859996032] mod_wsgi: Runtime using Python/3.5.2.
[Thu Apr 11 07:11:59.064588 2019] [mpm_event:notice] [pid 17741:tid 139660859996032] AH00489: Apache/2.4.18 (Ubuntu) mod_wsgi/4.3.0 Python/3.5.2 configured -- resuming normal operations
[Thu Apr 11 07:11:59.064619 2019] [core:notice] [pid 17741:tid 139660859996032] AH00094: Command line: '/usr/sbin/apache2'
[Thu Apr 11 14:12:38.927282 2019] [wsgi:error] [pid 17744:tid 139660600817408] [remote 107.9.188.191:57155] mod_wsgi (pid=17744): Exception occurred processing WSGI script '/var/www/portfolio/back/wsgi.py'.
[Thu Apr 11 14:12:38.930035 2019] [wsgi:error] [pid 17744:tid 139660600817408] [remote 107.9.188.191:57155] Traceback (most recent call last):
[Thu Apr 11 14:12:38.930118 2019] [wsgi:error] [pid 17744:tid 139660600817408] [remote 107.9.188.191:57155]   File "/home/kibblerz/pyenv/pyenv/lib/python3.5/site-packages/django/core/handlers/exception.py", line 34, in inner
[Thu Apr 11 14:12:38.930133 2019] [wsgi:error] [pid 17744:tid 139660600817408] [remote 107.9.188.191:57155]     response = get_response(request)
[Thu Apr 11 14:12:38.930157 2019] [wsgi:error] [pid 17744:tid 139660600817408] [remote 107.9.188.191:57155]   File "/home/kibblerz/pyenv/pyenv/lib/python3.5/site-packages/django/core/handlers/base.py", line 115, in _get_response
[Thu Apr 11 14:12:38.930170 2019] [wsgi:error] [pid 17744:tid 139660600817408] [remote 107.9.188.191:57155]     response = self.process_exception_by_middleware(e, request)
[Thu Apr 11 14:12:38.930192 2019] [wsgi:error] [pid 17744:tid 139660600817408] [remote 107.9.188.191:57155]   File "/home/kibblerz/pyenv/pyenv/lib/python3.5/site-packages/django/core/handlers/base.py", line 113, in _get_response
[Thu Apr 11 14:12:38.930204 2019] [wsgi:error] [pid 17744:tid 139660600817408] [remote 107.9.188.191:57155]     response = wrapped_callback(request, *callback_args, **callback_kwargs)
[Thu Apr 11 14:12:38.930225 2019] [wsgi:error] [pid 17744:tid 139660600817408] [remote 107.9.188.191:57155]   File "/var/www/portfolio/main/views.py", line 12, in contact
[Thu Apr 11 14:12:38.930236 2019] [wsgi:error] [pid 17744:tid 139660600817408] [remote 107.9.188.191:57155]     content = json.loads(request.body)
[Thu Apr 11 14:12:38.930260 2019] [wsgi:error] [pid 17744:tid 139660600817408] [remote 107.9.188.191:57155]   File "/usr/lib/python3.5/json/__init__.py", line 312, in loads
[Thu Apr 11 14:12:38.930272 2019] [wsgi:error] [pid 17744:tid 139660600817408] [remote 107.9.188.191:57155]     s.__class__.__name__))
[Thu Apr 11 14:12:38.930311 2019] [wsgi:error] [pid 17744:tid 139660600817408] [remote 107.9.188.191:57155] TypeError: the JSON object must be str, not 'bytes'
[Thu Apr 11 14:12:38.930342 2019] [wsgi:error] [pid 17744:tid 139660600817408] [remote 107.9.188.191:57155] 
[Thu Apr 11 14:12:38.930353 2019] [wsgi:error] [pid 17744:tid 139660600817408] [remote 107.9.188.191:57155] During handling of the above exception, another exception occurred:
[Thu Apr 11 14:12:38.930363 2019] [wsgi:error] [pid 17744:tid 139660600817408] [remote 107.9.188.191:57155] 
[Thu Apr 11 14:12:38.930383 2019] [wsgi:error] [pid 17744:tid 139660600817408] [remote 107.9.188.191:57155] Traceback (most recent call last):
[Thu Apr 11 14:12:38.930469 2019] [wsgi:error] [pid 17744:tid 139660600817408] [remote 107.9.188.191:57155]   File "/home/kibblerz/pyenv/pyenv/lib/python3.5/site-packages/django/core/handlers/exception.py", line 34, in inner
[Thu Apr 11 14:12:38.930482 2019] [wsgi:error] [pid 17744:tid 139660600817408] [remote 107.9.188.191:57155]     response = get_response(request)
[Thu Apr 11 14:12:38.930504 2019] [wsgi:error] [pid 17744:tid 139660600817408] [remote 107.9.188.191:57155]   File "/home/kibblerz/pyenv/pyenv/lib/python3.5/site-packages/django/utils/deprecation.py", line 94, in __call__
[Thu Apr 11 14:12:38.930517 2019] [wsgi:error] [pid 17744:tid 139660600817408] [remote 107.9.188.191:57155]     response = response or self.get_response(request)
[Thu Apr 11 14:12:38.930552 2019] [wsgi:error] [pid 17744:tid 139660600817408] [remote 107.9.188.191:57155]   File "/home/kibblerz/pyenv/pyenv/lib/python3.5/site-packages/django/core/handlers/exception.py", line 36, in inner
[Thu Apr 11 14:12:38.930563 2019] [wsgi:error] [pid 17744:tid 139660600817408] [remote 107.9.188.191:57155]     response = response_for_exception(request, exc)
[Thu Apr 11 14:12:38.930583 2019] [wsgi:error] [pid 17744:tid 139660600817408] [remote 107.9.188.191:57155]   File "/home/kibblerz/pyenv/pyenv/lib/python3.5/site-packages/django/core/handlers/exception.py", line 90, in response_for_exception
[Thu Apr 11 14:12:38.930594 2019] [wsgi:error] [pid 17744:tid 139660600817408] [remote 107.9.188.191:57155]     response = handle_uncaught_exception(request, get_resolver(get_urlconf()), sys.exc_info())
[Thu Apr 11 14:12:38.930626 2019] [wsgi:error] [pid 17744:tid 139660600817408] [remote 107.9.188.191:57155]   File "/home/kibblerz/pyenv/pyenv/lib/python3.5/site-packages/django/core/handlers/exception.py", line 125, in handle_uncaught_exception
[Thu Apr 11 14:12:38.930637 2019] [wsgi:error] [pid 17744:tid 139660600817408] [remote 107.9.188.191:57155]     return debug.technical_500_response(request, *exc_info)
[Thu Apr 11 14:12:38.930664 2019] [wsgi:error] [pid 17744:tid 139660600817408] [remote 107.9.188.191:57155]   File "/home/kibblerz/pyenv/pyenv/lib/python3.5/site-packages/django/views/debug.py", line 94, in technical_500_response
[Thu Apr 11 14:12:38.930675 2019] [wsgi:error] [pid 17744:tid 139660600817408] [remote 107.9.188.191:57155]     html = reporter.get_traceback_html()
[Thu Apr 11 14:12:38.930697 2019] [wsgi:error] [pid 17744:tid 139660600817408] [remote 107.9.188.191:57155]   File "/home/kibblerz/pyenv/pyenv/lib/python3.5/site-packages/django/views/debug.py", line 332, in get_traceback_html
[Thu Apr 11 14:12:38.930709 2019] [wsgi:error] [pid 17744:tid 139660600817408] [remote 107.9.188.191:57155]     t = DEBUG_ENGINE.from_string(fh.read())
[Thu Apr 11 14:12:38.930729 2019] [wsgi:error] [pid 17744:tid 139660600817408] [remote 107.9.188.191:57155]   File "/home/kibblerz/pyenv/pyenv/lib/python3.5/encodings/ascii.py", line 26, in decode
[Thu Apr 11 14:12:38.930739 2019] [wsgi:error] [pid 17744:tid 139660600817408] [remote 107.9.188.191:57155]     return codecs.ascii_decode(input, self.errors)[0]
[Thu Apr 11 14:12:38.930773 2019] [wsgi:error] [pid 17744:tid 139660600817408] [remote 107.9.188.191:57155] UnicodeDecodeError: 'ascii' codec can't decode byte 0xe2 in position 9735: ordinal not in range(128)
[Thu Apr 11 14:12:38.930801 2019] [wsgi:error] [pid 17744:tid 139660600817408] [remote 107.9.188.191:57155] 
[Thu Apr 11 14:12:38.930811 2019] [wsgi:error] [pid 17744:tid 139660600817408] [remote 107.9.188.191:57155] During handling of the above exception, another exception occurred:
[Thu Apr 11 14:12:38.930819 2019] [wsgi:error] [pid 17744:tid 139660600817408] [remote 107.9.188.191:57155] 
[Thu Apr 11 14:12:38.930839 2019] [wsgi:error] [pid 17744:tid 139660600817408] [remote 107.9.188.191:57155] Traceback (most recent call last):
[Thu Apr 11 14:12:38.930934 2019] [wsgi:error] [pid 17744:tid 139660600817408] [remote 107.9.188.191:57155]   File "/home/kibblerz/pyenv/pyenv/lib/python3.5/site-packages/django/core/handlers/exception.py", line 34, in inner
[Thu Apr 11 14:12:38.930946 2019] [wsgi:error] [pid 17744:tid 139660600817408] [remote 107.9.188.191:57155]     response = get_response(request)
[Thu Apr 11 14:12:38.930967 2019] [wsgi:error] [pid 17744:tid 139660600817408] [remote 107.9.188.191:57155]   File "/home/kibblerz/pyenv/pyenv/lib/python3.5/site-packages/django/utils/deprecation.py", line 94, in __call__
[Thu Apr 11 14:12:38.930977 2019] [wsgi:error] [pid 17744:tid 139660600817408] [remote 107.9.188.191:57155]     response = response or self.get_response(request)
[Thu Apr 11 14:12:38.930995 2019] [wsgi:error] [pid 17744:tid 139660600817408] [remote 107.9.188.191:57155]   File "/home/kibblerz/pyenv/pyenv/lib/python3.5/site-packages/django/core/handlers/exception.py", line 36, in inner
[Thu Apr 11 14:12:38.931014 2019] [wsgi:error] [pid 17744:tid 139660600817408] [remote 107.9.188.191:57155]     response = response_for_exception(request, exc)
[Thu Apr 11 14:12:38.931034 2019] [wsgi:error] [pid 17744:tid 139660600817408] [remote 107.9.188.191:57155]   File "/home/kibblerz/pyenv/pyenv/lib/python3.5/site-packages/django/core/handlers/exception.py", line 90, in response_for_exception
[Thu Apr 11 14:12:38.931045 2019] [wsgi:error] [pid 17744:tid 139660600817408] [remote 107.9.188.191:57155]     response = handle_uncaught_exception(request, get_resolver(get_urlconf()), sys.exc_info())
[Thu Apr 11 14:12:38.931064 2019] [wsgi:error] [pid 17744:tid 139660600817408] [remote 107.9.188.191:57155]   File "/home/kibblerz/pyenv/pyenv/lib/python3.5/site-packages/django/core/handlers/exception.py", line 125, in handle_uncaught_exception
[Thu Apr 11 14:12:38.931075 2019] [wsgi:error] [pid 17744:tid 139660600817408] [remote 107.9.188.191:57155]     return debug.technical_500_response(request, *exc_info)
[Thu Apr 11 14:12:38.931094 2019] [wsgi:error] [pid 17744:tid 139660600817408] [remote 107.9.188.191:57155]   File "/home/kibblerz/pyenv/pyenv/lib/python3.5/site-packages/django/views/debug.py", line 94, in technical_500_response
[Thu Apr 11 14:12:38.931104 2019] [wsgi:error] [pid 17744:tid 139660600817408] [remote 107.9.188.191:57155]     html = reporter.get_traceback_html()
[Thu Apr 11 14:12:38.931123 2019] [wsgi:error] [pid 17744:tid 139660600817408] [remote 107.9.188.191:57155]   File "/home/kibblerz/pyenv/pyenv/lib/python3.5/site-packages/django/views/debug.py", line 332, in get_traceback_html
[Thu Apr 11 14:12:38.931134 2019] [wsgi:error] [pid 17744:tid 139660600817408] [remote 107.9.188.191:57155]     t = DEBUG_ENGINE.from_string(fh.read())
[Thu Apr 11 14:12:38.931152 2019] [wsgi:error] [pid 17744:tid 139660600817408] [remote 107.9.188.191:57155]   File "/home/kibblerz/pyenv/pyenv/lib/python3.5/encodings/ascii.py", line 26, in decode
[Thu Apr 11 14:12:38.931162 2019] [wsgi:error] [pid 17744:tid 139660600817408] [remote 107.9.188.191:57155]     return codecs.ascii_decode(input, self.errors)[0]
[Thu Apr 11 14:12:38.931192 2019] [wsgi:error] [pid 17744:tid 139660600817408] [remote 107.9.188.191:57155] UnicodeDecodeError: 'ascii' codec can't decode byte 0xe2 in position 9735: ordinal not in range(128)
[Thu Apr 11 14:12:38.931216 2019] [wsgi:error] [pid 17744:tid 139660600817408] [remote 107.9.188.191:57155] 
[Thu Apr 11 14:12:38.931225 2019] [wsgi:error] [pid 17744:tid 139660600817408] [remote 107.9.188.191:57155] During handling of the above exception, another exception occurred:
[Thu Apr 11 14:12:38.931233 2019] [wsgi:error] [pid 17744:tid 139660600817408] [remote 107.9.188.191:57155] 
[Thu Apr 11 14:12:38.931251 2019] [wsgi:error] [pid 17744:tid 139660600817408] [remote 107.9.188.191:57155] Traceback (most recent call last):
[Thu Apr 11 14:12:38.931329 2019] [wsgi:error] [pid 17744:tid 139660600817408] [remote 107.9.188.191:57155]   File "/home/kibblerz/pyenv/pyenv/lib/python3.5/site-packages/django/core/handlers/exception.py", line 34, in inner
[Thu Apr 11 14:12:38.931342 2019] [wsgi:error] [pid 17744:tid 139660600817408] [remote 107.9.188.191:57155]     response = get_response(request)
[Thu Apr 11 14:12:38.931365 2019] [wsgi:error] [pid 17744:tid 139660600817408] [remote 107.9.188.191:57155]   File "/home/kibblerz/pyenv/pyenv/lib/python3.5/site-packages/django/utils/deprecation.py", line 94, in __call__
[Thu Apr 11 14:12:38.931376 2019] [wsgi:error] [pid 17744:tid 139660600817408] [remote 107.9.188.191:57155]     response = response or self.get_response(request)
[Thu Apr 11 14:12:38.931397 2019] [wsgi:error] [pid 17744:tid 139660600817408] [remote 107.9.188.191:57155]   File "/home/kibblerz/pyenv/pyenv/lib/python3.5/site-packages/django/core/handlers/exception.py", line 36, in inner
[Thu Apr 11 14:12:38.931409 2019] [wsgi:error] [pid 17744:tid 139660600817408] [remote 107.9.188.191:57155]     response = response_for_exception(request, exc)
[Thu Apr 11 14:12:38.931429 2019] [wsgi:error] [pid 17744:tid 139660600817408] [remote 107.9.188.191:57155]   File "/home/kibblerz/pyenv/pyenv/lib/python3.5/site-packages/django/core/handlers/exception.py", line 90, in response_for_exception
[Thu Apr 11 14:12:38.931448 2019] [wsgi:error] [pid 17744:tid 139660600817408] [remote 107.9.188.191:57155]     response = handle_uncaught_exception(request, get_resolver(get_urlconf()), sys.exc_info())
[Thu Apr 11 14:12:38.931470 2019] [wsgi:error] [pid 17744:tid 139660600817408] [remote 107.9.188.191:57155]   File "/home/kibblerz/pyenv/pyenv/lib/python3.5/site-packages/django/core/handlers/exception.py", line 125, in handle_uncaught_exception
[Thu Apr 11 14:12:38.931482 2019] [wsgi:error] [pid 17744:tid 139660600817408] [remote 107.9.188.191:57155]     return debug.technical_500_response(request, *exc_info)
[Thu Apr 11 14:12:38.931504 2019] [wsgi:error] [pid 17744:tid 139660600817408] [remote 107.9.188.191:57155]   File "/home/kibblerz/pyenv/pyenv/lib/python3.5/site-packages/django/views/debug.py", line 94, in technical_500_response
[Thu Apr 11 14:12:38.931517 2019] [wsgi:error] [pid 17744:tid 139660600817408] [remote 107.9.188.191:57155]     html = reporter.get_traceback_html()
[Thu Apr 11 14:12:38.931537 2019] [wsgi:error] [pid 17744:tid 139660600817408] [remote 107.9.188.191:57155]   File "/home/kibblerz/pyenv/pyenv/lib/python3.5/site-packages/django/views/debug.py", line 332, in get_traceback_html
[Thu Apr 11 14:12:38.931550 2019] [wsgi:error] [pid 17744:tid 139660600817408] [remote 107.9.188.191:57155]     t = DEBUG_ENGINE.from_string(fh.read())
[Thu Apr 11 14:12:38.931570 2019] [wsgi:error] [pid 17744:tid 139660600817408] [remote 107.9.188.191:57155]   File "/home/kibblerz/pyenv/pyenv/lib/python3.5/encodings/ascii.py", line 26, in decode
[Thu Apr 11 14:12:38.931581 2019] [wsgi:error] [pid 17744:tid 139660600817408] [remote 107.9.188.191:57155]     return codecs.ascii_decode(input, self.errors)[0]
[Thu Apr 11 14:12:38.931632 2019] [wsgi:error] [pid 17744:tid 139660600817408] [remote 107.9.188.191:57155] UnicodeDecodeError: 'ascii' codec can't decode byte 0xe2 in position 9735: ordinal not in range(128)
[Thu Apr 11 14:12:38.931668 2019] [wsgi:error] [pid 17744:tid 139660600817408] [remote 107.9.188.191:57155] 
[Thu Apr 11 14:12:38.931679 2019] [wsgi:error] [pid 17744:tid 139660600817408] [remote 107.9.188.191:57155] During handling of the above exception, another exception occurred:
[Thu Apr 11 14:12:38.931687 2019] [wsgi:error] [pid 17744:tid 139660600817408] [remote 107.9.188.191:57155] 
[Thu Apr 11 14:12:38.931709 2019] [wsgi:error] [pid 17744:tid 139660600817408] [remote 107.9.188.191:57155] Traceback (most recent call last):
[Thu Apr 11 14:12:38.931792 2019] [wsgi:error] [pid 17744:tid 139660600817408] [remote 107.9.188.191:57155]   File "/home/kibblerz/pyenv/pyenv/lib/python3.5/site-packages/django/core/handlers/exception.py", line 34, in inner
[Thu Apr 11 14:12:38.931805 2019] [wsgi:error] [pid 17744:tid 139660600817408] [remote 107.9.188.191:57155]     response = get_response(request)
[Thu Apr 11 14:12:38.931826 2019] [wsgi:error] [pid 17744:tid 139660600817408] [remote 107.9.188.191:57155]   File "/home/kibblerz/pyenv/pyenv/lib/python3.5/site-packages/django/utils/deprecation.py", line 94, in __call__
[Thu Apr 11 14:12:38.931838 2019] [wsgi:error] [pid 17744:tid 139660600817408] [remote 107.9.188.191:57155]     response = response or self.get_response(request)
[Thu Apr 11 14:12:38.931857 2019] [wsgi:error] [pid 17744:tid 139660600817408] [remote 107.9.188.191:57155]   File "/home/kibblerz/pyenv/pyenv/lib/python3.5/site-packages/django/core/handlers/exception.py", line 36, in inner
[Thu Apr 11 14:12:38.931868 2019] [wsgi:error] [pid 17744:tid 139660600817408] [remote 107.9.188.191:57155]     response = response_for_exception(request, exc)
[Thu Apr 11 14:12:38.931887 2019] [wsgi:error] [pid 17744:tid 139660600817408] [remote 107.9.188.191:57155]   File "/home/kibblerz/pyenv/pyenv/lib/python3.5/site-packages/django/core/handlers/exception.py", line 90, in response_for_exception
[Thu Apr 11 14:12:38.931898 2019] [wsgi:error] [pid 17744:tid 139660600817408] [remote 107.9.188.191:57155]     response = handle_uncaught_exception(request, get_resolver(get_urlconf()), sys.exc_info())
[Thu Apr 11 14:12:38.931938 2019] [wsgi:error] [pid 17744:tid 139660600817408] [remote 107.9.188.191:57155]   File "/home/kibblerz/pyenv/pyenv/lib/python3.5/site-packages/django/core/handlers/exception.py", line 125, in handle_uncaught_exception
[Thu Apr 11 14:12:38.931950 2019] [wsgi:error] [pid 17744:tid 139660600817408] [remote 107.9.188.191:57155]     return debug.technical_500_response(request, *exc_info)
[Thu Apr 11 14:12:38.931971 2019] [wsgi:error] [pid 17744:tid 139660600817408] [remote 107.9.188.191:57155]   File "/home/kibblerz/pyenv/pyenv/lib/python3.5/site-packages/django/views/debug.py", line 94, in technical_500_response
[Thu Apr 11 14:12:38.931981 2019] [wsgi:error] [pid 17744:tid 139660600817408] [remote 107.9.188.191:57155]     html = reporter.get_traceback_html()
[Thu Apr 11 14:12:38.932002 2019] [wsgi:error] [pid 17744:tid 139660600817408] [remote 107.9.188.191:57155]   File "/home/kibblerz/pyenv/pyenv/lib/python3.5/site-packages/django/views/debug.py", line 332, in get_traceback_html
[Thu Apr 11 14:12:38.932012 2019] [wsgi:error] [pid 17744:tid 139660600817408] [remote 107.9.188.191:57155]     t = DEBUG_ENGINE.from_string(fh.read())
[Thu Apr 11 14:12:38.932032 2019] [wsgi:error] [pid 17744:tid 139660600817408] [remote 107.9.188.191:57155]   File "/home/kibblerz/pyenv/pyenv/lib/python3.5/encodings/ascii.py", line 26, in decode
[Thu Apr 11 14:12:38.932043 2019] [wsgi:error] [pid 17744:tid 139660600817408] [remote 107.9.188.191:57155]     return codecs.ascii_decode(input, self.errors)[0]
[Thu Apr 11 14:12:38.932075 2019] [wsgi:error] [pid 17744:tid 139660600817408] [remote 107.9.188.191:57155] UnicodeDecodeError: 'ascii' codec can't decode byte 0xe2 in position 9735: ordinal not in range(128)
[Thu Apr 11 14:12:38.932100 2019] [wsgi:error] [pid 17744:tid 139660600817408] [remote 107.9.188.191:57155] 
[Thu Apr 11 14:12:38.932111 2019] [wsgi:error] [pid 17744:tid 139660600817408] [remote 107.9.188.191:57155] During handling of the above exception, another exception occurred:
[Thu Apr 11 14:12:38.932119 2019] [wsgi:error] [pid 17744:tid 139660600817408] [remote 107.9.188.191:57155] 
[Thu Apr 11 14:12:38.932139 2019] [wsgi:error] [pid 17744:tid 139660600817408] [remote 107.9.188.191:57155] Traceback (most recent call last):
[Thu Apr 11 14:12:38.932235 2019] [wsgi:error] [pid 17744:tid 139660600817408] [remote 107.9.188.191:57155]   File "/home/kibblerz/pyenv/pyenv/lib/python3.5/site-packages/django/core/handlers/exception.py", line 34, in inner
[Thu Apr 11 14:12:38.932248 2019] [wsgi:error] [pid 17744:tid 139660600817408] [remote 107.9.188.191:57155]     response = get_response(request)
[Thu Apr 11 14:12:38.932269 2019] [wsgi:error] [pid 17744:tid 139660600817408] [remote 107.9.188.191:57155]   File "/home/kibblerz/pyenv/pyenv/lib/python3.5/site-packages/django/utils/deprecation.py", line 94, in __call__
[Thu Apr 11 14:12:38.932281 2019] [wsgi:error] [pid 17744:tid 139660600817408] [remote 107.9.188.191:57155]     response = response or self.get_response(request)
[Thu Apr 11 14:12:38.932301 2019] [wsgi:error] [pid 17744:tid 139660600817408] [remote 107.9.188.191:57155]   File "/home/kibblerz/pyenv/pyenv/lib/python3.5/site-packages/django/core/handlers/exception.py", line 36, in inner
[Thu Apr 11 14:12:38.932312 2019] [wsgi:error] [pid 17744:tid 139660600817408] [remote 107.9.188.191:57155]     response = response_for_exception(request, exc)
[Thu Apr 11 14:12:38.932331 2019] [wsgi:error] [pid 17744:tid 139660600817408] [remote 107.9.188.191:57155]   File "/home/kibblerz/pyenv/pyenv/lib/python3.5/site-packages/django/core/handlers/exception.py", line 90, in response_for_exception
[Thu Apr 11 14:12:38.932343 2019] [wsgi:error] [pid 17744:tid 139660600817408] [remote 107.9.188.191:57155]     response = handle_uncaught_exception(request, get_resolver(get_urlconf()), sys.exc_info())
[Thu Apr 11 14:12:38.932363 2019] [wsgi:error] [pid 17744:tid 139660600817408] [remote 107.9.188.191:57155]   File "/home/kibblerz/pyenv/pyenv/lib/python3.5/site-packages/django/core/handlers/exception.py", line 125, in handle_uncaught_exception
[Thu Apr 11 14:12:38.932383 2019] [wsgi:error] [pid 17744:tid 139660600817408] [remote 107.9.188.191:57155]     return debug.technical_500_response(request, *exc_info)
[Thu Apr 11 14:12:38.932405 2019] [wsgi:error] [pid 17744:tid 139660600817408] [remote 107.9.188.191:57155]   File "/home/kibblerz/pyenv/pyenv/lib/python3.5/site-packages/django/views/debug.py", line 94, in technical_500_response
[Thu Apr 11 14:12:38.932418 2019] [wsgi:error] [pid 17744:tid 139660600817408] [remote 107.9.188.191:57155]     html = reporter.get_traceback_html()
[Thu Apr 11 14:12:38.932438 2019] [wsgi:error] [pid 17744:tid 139660600817408] [remote 107.9.188.191:57155]   File "/home/kibblerz/pyenv/pyenv/lib/python3.5/site-packages/django/views/debug.py", line 332, in get_traceback_html
[Thu Apr 11 14:12:38.932450 2019] [wsgi:error] [pid 17744:tid 139660600817408] [remote 107.9.188.191:57155]     t = DEBUG_ENGINE.from_string(fh.read())
[Thu Apr 11 14:12:38.932482 2019] [wsgi:error] [pid 17744:tid 139660600817408] [remote 107.9.188.191:57155]   File "/home/kibblerz/pyenv/pyenv/lib/python3.5/encodings/ascii.py", line 26, in decode
[Thu Apr 11 14:12:38.932493 2019] [wsgi:error] [pid 17744:tid 139660600817408] [remote 107.9.188.191:57155]     return codecs.ascii_decode(input, self.errors)[0]
[Thu Apr 11 14:12:38.932534 2019] [wsgi:error] [pid 17744:tid 139660600817408] [remote 107.9.188.191:57155] UnicodeDecodeError: 'ascii' codec can't decode byte 0xe2 in position 9735: ordinal not in range(128)
[Thu Apr 11 14:12:38.932561 2019] [wsgi:error] [pid 17744:tid 139660600817408] [remote 107.9.188.191:57155] 
[Thu Apr 11 14:12:38.932571 2019] [wsgi:error] [pid 17744:tid 139660600817408] [remote 107.9.188.191:57155] During handling of the above exception, another exception occurred:
[Thu Apr 11 14:12:38.932579 2019] [wsgi:error] [pid 17744:tid 139660600817408] [remote 107.9.188.191:57155] 
[Thu Apr 11 14:12:38.932600 2019] [wsgi:error] [pid 17744:tid 139660600817408] [remote 107.9.188.191:57155] Traceback (most recent call last):
[Thu Apr 11 14:12:38.932710 2019] [wsgi:error] [pid 17744:tid 139660600817408] [remote 107.9.188.191:57155]   File "/home/kibblerz/pyenv/pyenv/lib/python3.5/site-packages/django/core/handlers/exception.py", line 34, in inner
[Thu Apr 11 14:12:38.932726 2019] [wsgi:error] [pid 17744:tid 139660600817408] [remote 107.9.188.191:57155]     response = get_response(request)
[Thu Apr 11 14:12:38.932748 2019] [wsgi:error] [pid 17744:tid 139660600817408] [remote 107.9.188.191:57155]   File "/home/kibblerz/pyenv/pyenv/lib/python3.5/site-packages/django/utils/deprecation.py", line 94, in __call__
[Thu Apr 11 14:12:38.932760 2019] [wsgi:error] [pid 17744:tid 139660600817408] [remote 107.9.188.191:57155]     response = response or self.get_response(request)
[Thu Apr 11 14:12:38.932780 2019] [wsgi:error] [pid 17744:tid 139660600817408] [remote 107.9.188.191:57155]   File "/home/kibblerz/pyenv/pyenv/lib/python3.5/site-packages/django/core/handlers/exception.py", line 36, in inner
[Thu Apr 11 14:12:38.932792 2019] [wsgi:error] [pid 17744:tid 139660600817408] [remote 107.9.188.191:57155]     response = response_for_exception(request, exc)
[Thu Apr 11 14:12:38.932813 2019] [wsgi:error] [pid 17744:tid 139660600817408] [remote 107.9.188.191:57155]   File "/home/kibblerz/pyenv/pyenv/lib/python3.5/site-packages/django/core/handlers/exception.py", line 90, in response_for_exception
[Thu Apr 11 14:12:38.932825 2019] [wsgi:error] [pid 17744:tid 139660600817408] [remote 107.9.188.191:57155]     response = handle_uncaught_exception(request, get_resolver(get_urlconf()), sys.exc_info())
[Thu Apr 11 14:12:38.932847 2019] [wsgi:error] [pid 17744:tid 139660600817408] [remote 107.9.188.191:57155]   File "/home/kibblerz/pyenv/pyenv/lib/python3.5/site-packages/django/core/handlers/exception.py", line 125, in handle_uncaught_exception
[Thu Apr 11 14:12:38.932859 2019] [wsgi:error] [pid 17744:tid 139660600817408] [remote 107.9.188.191:57155]     return debug.technical_500_response(request, *exc_info)
[Thu Apr 11 14:12:38.932887 2019] [wsgi:error] [pid 17744:tid 139660600817408] [remote 107.9.188.191:57155]   File "/home/kibblerz/pyenv/pyenv/lib/python3.5/site-packages/django/views/debug.py", line 94, in technical_500_response
[Thu Apr 11 14:12:38.932899 2019] [wsgi:error] [pid 17744:tid 139660600817408] [remote 107.9.188.191:57155]     html = reporter.get_traceback_html()
[Thu Apr 11 14:12:38.932918 2019] [wsgi:error] [pid 17744:tid 139660600817408] [remote 107.9.188.191:57155]   File "/home/kibblerz/pyenv/pyenv/lib/python3.5/site-packages/django/views/debug.py", line 332, in get_traceback_html
[Thu Apr 11 14:12:38.932929 2019] [wsgi:error] [pid 17744:tid 139660600817408] [remote 107.9.188.191:57155]     t = DEBUG_ENGINE.from_string(fh.read())
[Thu Apr 11 14:12:38.932949 2019] [wsgi:error] [pid 17744:tid 139660600817408] [remote 107.9.188.191:57155]   File "/home/kibblerz/pyenv/pyenv/lib/python3.5/encodings/ascii.py", line 26, in decode
[Thu Apr 11 14:12:38.932960 2019] [wsgi:error] [pid 17744:tid 139660600817408] [remote 107.9.188.191:57155]     return codecs.ascii_decode(input, self.errors)[0]
[Thu Apr 11 14:12:38.932996 2019] [wsgi:error] [pid 17744:tid 139660600817408] [remote 107.9.188.191:57155] UnicodeDecodeError: 'ascii' codec can't decode byte 0xe2 in position 9735: ordinal not in range(128)
[Thu Apr 11 14:12:38.933022 2019] [wsgi:error] [pid 17744:tid 139660600817408] [remote 107.9.188.191:57155] 
[Thu Apr 11 14:12:38.933033 2019] [wsgi:error] [pid 17744:tid 139660600817408] [remote 107.9.188.191:57155] During handling of the above exception, another exception occurred:
[Thu Apr 11 14:12:38.933041 2019] [wsgi:error] [pid 17744:tid 139660600817408] [remote 107.9.188.191:57155] 
[Thu Apr 11 14:12:38.933062 2019] [wsgi:error] [pid 17744:tid 139660600817408] [remote 107.9.188.191:57155] Traceback (most recent call last):
[Thu Apr 11 14:12:38.933146 2019] [wsgi:error] [pid 17744:tid 139660600817408] [remote 107.9.188.191:57155]   File "/home/kibblerz/pyenv/pyenv/lib/python3.5/site-packages/django/core/handlers/exception.py", line 34, in inner
[Thu Apr 11 14:12:38.933171 2019] [wsgi:error] [pid 17744:tid 139660600817408] [remote 107.9.188.191:57155]     response = get_response(request)
[Thu Apr 11 14:12:38.933191 2019] [wsgi:error] [pid 17744:tid 139660600817408] [remote 107.9.188.191:57155]   File "/home/kibblerz/pyenv/pyenv/lib/python3.5/site-packages/django/utils/deprecation.py", line 94, in __call__
[Thu Apr 11 14:12:38.933203 2019] [wsgi:error] [pid 17744:tid 139660600817408] [remote 107.9.188.191:57155]     response = response or self.get_response(request)
[Thu Apr 11 14:12:38.933222 2019] [wsgi:error] [pid 17744:tid 139660600817408] [remote 107.9.188.191:57155]   File "/home/kibblerz/pyenv/pyenv/lib/python3.5/site-packages/django/core/handlers/exception.py", line 36, in inner
[Thu Apr 11 14:12:38.933233 2019] [wsgi:error] [pid 17744:tid 139660600817408] [remote 107.9.188.191:57155]     response = response_for_exception(request, exc)
[Thu Apr 11 14:12:38.933253 2019] [wsgi:error] [pid 17744:tid 139660600817408] [remote 107.9.188.191:57155]   File "/home/kibblerz/pyenv/pyenv/lib/python3.5/site-packages/django/core/handlers/exception.py", line 90, in response_for_exception
[Thu Apr 11 14:12:38.933265 2019] [wsgi:error] [pid 17744:tid 139660600817408] [remote 107.9.188.191:57155]     response = handle_uncaught_exception(request, get_resolver(get_urlconf()), sys.exc_info())
[Thu Apr 11 14:12:38.933285 2019] [wsgi:error] [pid 17744:tid 139660600817408] [remote 107.9.188.191:57155]   File "/home/kibblerz/pyenv/pyenv/lib/python3.5/site-packages/django/core/handlers/exception.py", line 125, in handle_uncaught_exception
[Thu Apr 11 14:12:38.933296 2019] [wsgi:error] [pid 17744:tid 139660600817408] [remote 107.9.188.191:57155]     return debug.technical_500_response(request, *exc_info)
[Thu Apr 11 14:12:38.933316 2019] [wsgi:error] [pid 17744:tid 139660600817408] [remote 107.9.188.191:57155]   File "/home/kibblerz/pyenv/pyenv/lib/python3.5/site-packages/django/views/debug.py", line 94, in technical_500_response
[Thu Apr 11 14:12:38.933337 2019] [wsgi:error] [pid 17744:tid 139660600817408] [remote 107.9.188.191:57155]     html = reporter.get_traceback_html()
[Thu Apr 11 14:12:38.933370 2019] [wsgi:error] [pid 17744:tid 139660600817408] [remote 107.9.188.191:57155]   File "/home/kibblerz/pyenv/pyenv/lib/python3.5/site-packages/django/views/debug.py", line 332, in get_traceback_html
[Thu Apr 11 14:12:38.933382 2019] [wsgi:error] [pid 17744:tid 139660600817408] [remote 107.9.188.191:57155]     t = DEBUG_ENGINE.from_string(fh.read())
[Thu Apr 11 14:12:38.933402 2019] [wsgi:error] [pid 17744:tid 139660600817408] [remote 107.9.188.191:57155]   File "/home/kibblerz/pyenv/pyenv/lib/python3.5/encodings/ascii.py", line 26, in decode
[Thu Apr 11 14:12:38.933412 2019] [wsgi:error] [pid 17744:tid 139660600817408] [remote 107.9.188.191:57155]     return codecs.ascii_decode(input, self.errors)[0]
[Thu Apr 11 14:12:38.933447 2019] [wsgi:error] [pid 17744:tid 139660600817408] [remote 107.9.188.191:57155] UnicodeDecodeError: 'ascii' codec can't decode byte 0xe2 in position 9735: ordinal not in range(128)
[Thu Apr 11 14:12:38.933474 2019] [wsgi:error] [pid 17744:tid 139660600817408] [remote 107.9.188.191:57155] 
[Thu Apr 11 14:12:38.933486 2019] [wsgi:error] [pid 17744:tid 139660600817408] [remote 107.9.188.191:57155] During handling of the above exception, another exception occurred:
[Thu Apr 11 14:12:38.933494 2019] [wsgi:error] [pid 17744:tid 139660600817408] [remote 107.9.188.191:57155] 
[Thu Apr 11 14:12:38.933514 2019] [wsgi:error] [pid 17744:tid 139660600817408] [remote 107.9.188.191:57155] Traceback (most recent call last):
[Thu Apr 11 14:12:38.933599 2019] [wsgi:error] [pid 17744:tid 139660600817408] [remote 107.9.188.191:57155]   File "/home/kibblerz/pyenv/pyenv/lib/python3.5/site-packages/django/core/handlers/wsgi.py", line 141, in __call__
[Thu Apr 11 14:12:38.933613 2019] [wsgi:error] [pid 17744:tid 139660600817408] [remote 107.9.188.191:57155]     response = self.get_response(request)
[Thu Apr 11 14:12:38.933633 2019] [wsgi:error] [pid 17744:tid 139660600817408] [remote 107.9.188.191:57155]   File "/home/kibblerz/pyenv/pyenv/lib/python3.5/site-packages/django/core/handlers/base.py", line 75, in get_response
[Thu Apr 11 14:12:38.933651 2019] [wsgi:error] [pid 17744:tid 139660600817408] [remote 107.9.188.191:57155]     response = self._middleware_chain(request)
[Thu Apr 11 14:12:38.933680 2019] [wsgi:error] [pid 17744:tid 139660600817408] [remote 107.9.188.191:57155]   File "/home/kibblerz/pyenv/pyenv/lib/python3.5/site-packages/django/core/handlers/exception.py", line 36, in inner
[Thu Apr 11 14:12:38.933695 2019] [wsgi:error] [pid 17744:tid 139660600817408] [remote 107.9.188.191:57155]     response = response_for_exception(request, exc)
[Thu Apr 11 14:12:38.933717 2019] [wsgi:error] [pid 17744:tid 139660600817408] [remote 107.9.188.191:57155]   File "/home/kibblerz/pyenv/pyenv/lib/python3.5/site-packages/django/core/handlers/exception.py", line 90, in response_for_exception
[Thu Apr 11 14:12:38.933730 2019] [wsgi:error] [pid 17744:tid 139660600817408] [remote 107.9.188.191:57155]     response = handle_uncaught_exception(request, get_resolver(get_urlconf()), sys.exc_info())
[Thu Apr 11 14:12:38.933750 2019] [wsgi:error] [pid 17744:tid 139660600817408] [remote 107.9.188.191:57155]   File "/home/kibblerz/pyenv/pyenv/lib/python3.5/site-packages/django/core/handlers/exception.py", line 125, in handle_uncaught_exception
[Thu Apr 11 14:12:38.933761 2019] [wsgi:error] [pid 17744:tid 139660600817408] [remote 107.9.188.191:57155]     return debug.technical_500_response(request, *exc_info)
[Thu Apr 11 14:12:38.933780 2019] [wsgi:error] [pid 17744:tid 139660600817408] [remote 107.9.188.191:57155]   File "/home/kibblerz/pyenv/pyenv/lib/python3.5/site-packages/django/views/debug.py", line 94, in technical_500_response
[Thu Apr 11 14:12:38.933791 2019] [wsgi:error] [pid 17744:tid 139660600817408] [remote 107.9.188.191:57155]     html = reporter.get_traceback_html()
[Thu Apr 11 14:12:38.933820 2019] [wsgi:error] [pid 17744:tid 139660600817408] [remote 107.9.188.191:57155]   File "/home/kibblerz/pyenv/pyenv/lib/python3.5/site-packages/django/views/debug.py", line 332, in get_traceback_html
[Thu Apr 11 14:12:38.933832 2019] [wsgi:error] [pid 17744:tid 139660600817408] [remote 107.9.188.191:57155]     t = DEBUG_ENGINE.from_string(fh.read())
[Thu Apr 11 14:12:38.933852 2019] [wsgi:error] [pid 17744:tid 139660600817408] [remote 107.9.188.191:57155]   File "/home/kibblerz/pyenv/pyenv/lib/python3.5/encodings/ascii.py", line 26, in decode
[Thu Apr 11 14:12:38.933863 2019] [wsgi:error] [pid 17744:tid 139660600817408] [remote 107.9.188.191:57155]     return codecs.ascii_decode(input, self.errors)[0]
[Thu Apr 11 14:12:38.933896 2019] [wsgi:error] [pid 17744:tid 139660600817408] [remote 107.9.188.191:57155] UnicodeDecodeError: 'ascii' codec can't decode byte 0xe2 in position 9735: ordinal not in range(128)
[Thu Apr 11 14:14:34.411920 2019] [wsgi:error] [pid 17744:tid 139660747806464] Invalid HTTP_HOST header: 'newthoughtedu.com'. You may need to add 'newthoughtedu.com' to ALLOWED_HOSTS.
[Thu Apr 11 14:14:34.412571 2019] [wsgi:error] [pid 17744:tid 139660747806464] [remote 66.249.65.126:40768] mod_wsgi (pid=17744): Exception occurred processing WSGI script '/var/www/portfolio/back/wsgi.py'.
[Thu Apr 11 14:14:34.413440 2019] [wsgi:error] [pid 17744:tid 139660747806464] [remote 66.249.65.126:40768] Traceback (most recent call last):
[Thu Apr 11 14:14:34.413486 2019] [wsgi:error] [pid 17744:tid 139660747806464] [remote 66.249.65.126:40768]   File "/home/kibblerz/pyenv/pyenv/lib/python3.5/site-packages/django/core/handlers/exception.py", line 34, in inner
[Thu Apr 11 14:14:34.413496 2019] [wsgi:error] [pid 17744:tid 139660747806464] [remote 66.249.65.126:40768]     response = get_response(request)
[Thu Apr 11 14:14:34.413509 2019] [wsgi:error] [pid 17744:tid 139660747806464] [remote 66.249.65.126:40768]   File "/home/kibblerz/pyenv/pyenv/lib/python3.5/site-packages/django/utils/deprecation.py", line 93, in __call__
[Thu Apr 11 14:14:34.413516 2019] [wsgi:error] [pid 17744:tid 139660747806464] [remote 66.249.65.126:40768]     response = self.process_request(request)
[Thu Apr 11 14:14:34.413528 2019] [wsgi:error] [pid 17744:tid 139660747806464] [remote 66.249.65.126:40768]   File "/home/kibblerz/pyenv/pyenv/lib/python3.5/site-packages/django/middleware/common.py", line 47, in process_request
[Thu Apr 11 14:14:34.413534 2019] [wsgi:error] [pid 17744:tid 139660747806464] [remote 66.249.65.126:40768]     host = request.get_host()
[Thu Apr 11 14:14:34.413546 2019] [wsgi:error] [pid 17744:tid 139660747806464] [remote 66.249.65.126:40768]   File "/home/kibblerz/pyenv/pyenv/lib/python3.5/site-packages/django/http/request.py", line 111, in get_host
[Thu Apr 11 14:14:34.413553 2019] [wsgi:error] [pid 17744:tid 139660747806464] [remote 66.249.65.126:40768]     raise DisallowedHost(msg)
[Thu Apr 11 14:14:34.413576 2019] [wsgi:error] [pid 17744:tid 139660747806464] [remote 66.249.65.126:40768] django.core.exceptions.DisallowedHost: Invalid HTTP_HOST header: 'newthoughtedu.com'. You may need to add 'newthoughtedu.com' to ALLOWED_HOSTS.
[Thu Apr 11 14:14:34.413592 2019] [wsgi:error] [pid 17744:tid 139660747806464] [remote 66.249.65.126:40768] 
[Thu Apr 11 14:14:34.413599 2019] [wsgi:error] [pid 17744:tid 139660747806464] [remote 66.249.65.126:40768] During handling of the above exception, another exception occurred:
[Thu Apr 11 14:14:34.413604 2019] [wsgi:error] [pid 17744:tid 139660747806464] [remote 66.249.65.126:40768] 
[Thu Apr 11 14:14:34.413616 2019] [wsgi:error] [pid 17744:tid 139660747806464] [remote 66.249.65.126:40768] Traceback (most recent call last):
[Thu Apr 11 14:14:34.413680 2019] [wsgi:error] [pid 17744:tid 139660747806464] [remote 66.249.65.126:40768]   File "/home/kibblerz/pyenv/pyenv/lib/python3.5/site-packages/django/core/handlers/exception.py", line 34, in inner
[Thu Apr 11 14:14:34.413690 2019] [wsgi:error] [pid 17744:tid 139660747806464] [remote 66.249.65.126:40768]     response = get_response(request)
[Thu Apr 11 14:14:34.413717 2019] [wsgi:error] [pid 17744:tid 139660747806464] [remote 66.249.65.126:40768]   File "/home/kibblerz/pyenv/pyenv/lib/python3.5/site-packages/django/utils/deprecation.py", line 94, in __call__
[Thu Apr 11 14:14:34.413724 2019] [wsgi:error] [pid 17744:tid 139660747806464] [remote 66.249.65.126:40768]     response = response or self.get_response(request)
[Thu Apr 11 14:14:34.413735 2019] [wsgi:error] [pid 17744:tid 139660747806464] [remote 66.249.65.126:40768]   File "/home/kibblerz/pyenv/pyenv/lib/python3.5/site-packages/django/core/handlers/exception.py", line 36, in inner
[Thu Apr 11 14:14:34.413742 2019] [wsgi:error] [pid 17744:tid 139660747806464] [remote 66.249.65.126:40768]     response = response_for_exception(request, exc)
[Thu Apr 11 14:14:34.413753 2019] [wsgi:error] [pid 17744:tid 139660747806464] [remote 66.249.65.126:40768]   File "/home/kibblerz/pyenv/pyenv/lib/python3.5/site-packages/django/core/handlers/exception.py", line 80, in response_for_exception
[Thu Apr 11 14:14:34.413760 2019] [wsgi:error] [pid 17744:tid 139660747806464] [remote 66.249.65.126:40768]     response = debug.technical_500_response(request, *sys.exc_info(), status_code=400)
[Thu Apr 11 14:14:34.413771 2019] [wsgi:error] [pid 17744:tid 139660747806464] [remote 66.249.65.126:40768]   File "/home/kibblerz/pyenv/pyenv/lib/python3.5/site-packages/django/views/debug.py", line 94, in technical_500_response
[Thu Apr 11 14:14:34.413778 2019] [wsgi:error] [pid 17744:tid 139660747806464] [remote 66.249.65.126:40768]     html = reporter.get_traceback_html()
[Thu Apr 11 14:14:34.413789 2019] [wsgi:error] [pid 17744:tid 139660747806464] [remote 66.249.65.126:40768]   File "/home/kibblerz/pyenv/pyenv/lib/python3.5/site-packages/django/views/debug.py", line 332, in get_traceback_html
[Thu Apr 11 14:14:34.413795 2019] [wsgi:error] [pid 17744:tid 139660747806464] [remote 66.249.65.126:40768]     t = DEBUG_ENGINE.from_string(fh.read())
[Thu Apr 11 14:14:34.413806 2019] [wsgi:error] [pid 17744:tid 139660747806464] [remote 66.249.65.126:40768]   File "/home/kibblerz/pyenv/pyenv/lib/python3.5/encodings/ascii.py", line 26, in decode
[Thu Apr 11 14:14:34.413812 2019] [wsgi:error] [pid 17744:tid 139660747806464] [remote 66.249.65.126:40768]     return codecs.ascii_decode(input, self.errors)[0]
[Thu Apr 11 14:14:34.413831 2019] [wsgi:error] [pid 17744:tid 139660747806464] [remote 66.249.65.126:40768] UnicodeDecodeError: 'ascii' codec can't decode byte 0xe2 in position 9735: ordinal not in range(128)
[Thu Apr 11 14:14:34.413846 2019] [wsgi:error] [pid 17744:tid 139660747806464] [remote 66.249.65.126:40768] 
[Thu Apr 11 14:14:34.413852 2019] [wsgi:error] [pid 17744:tid 139660747806464] [remote 66.249.65.126:40768] During handling of the above exception, another exception occurred:
[Thu Apr 11 14:14:34.413858 2019] [wsgi:error] [pid 17744:tid 139660747806464] [remote 66.249.65.126:40768] 
[Thu Apr 11 14:14:34.413868 2019] [wsgi:error] [pid 17744:tid 139660747806464] [remote 66.249.65.126:40768] Traceback (most recent call last):
[Thu Apr 11 14:14:34.413911 2019] [wsgi:error] [pid 17744:tid 139660747806464] [remote 66.249.65.126:40768]   File "/home/kibblerz/pyenv/pyenv/lib/python3.5/site-packages/django/core/handlers/exception.py", line 34, in inner
[Thu Apr 11 14:14:34.413919 2019] [wsgi:error] [pid 17744:tid 139660747806464] [remote 66.249.65.126:40768]     response = get_response(request)
[Thu Apr 11 14:14:34.413930 2019] [wsgi:error] [pid 17744:tid 139660747806464] [remote 66.249.65.126:40768]   File "/home/kibblerz/pyenv/pyenv/lib/python3.5/site-packages/django/utils/deprecation.py", line 94, in __call__
[Thu Apr 11 14:14:34.413937 2019] [wsgi:error] [pid 17744:tid 139660747806464] [remote 66.249.65.126:40768]     response = response or self.get_response(request)
[Thu Apr 11 14:14:34.413947 2019] [wsgi:error] [pid 17744:tid 139660747806464] [remote 66.249.65.126:40768]   File "/home/kibblerz/pyenv/pyenv/lib/python3.5/site-packages/django/core/handlers/exception.py", line 36, in inner
[Thu Apr 11 14:14:34.413954 2019] [wsgi:error] [pid 17744:tid 139660747806464] [remote 66.249.65.126:40768]     response = response_for_exception(request, exc)
[Thu Apr 11 14:14:34.413983 2019] [wsgi:error] [pid 17744:tid 139660747806464] [remote 66.249.65.126:40768]   File "/home/kibblerz/pyenv/pyenv/lib/python3.5/site-packages/django/core/handlers/exception.py", line 90, in response_for_exception
[Thu Apr 11 14:14:34.413990 2019] [wsgi:error] [pid 17744:tid 139660747806464] [remote 66.249.65.126:40768]     response = handle_uncaught_exception(request, get_resolver(get_urlconf()), sys.exc_info())
[Thu Apr 11 14:14:34.414001 2019] [wsgi:error] [pid 17744:tid 139660747806464] [remote 66.249.65.126:40768]   File "/home/kibblerz/pyenv/pyenv/lib/python3.5/site-packages/django/core/handlers/exception.py", line 125, in handle_uncaught_exception
[Thu Apr 11 14:14:34.414007 2019] [wsgi:error] [pid 17744:tid 139660747806464] [remote 66.249.65.126:40768]     return debug.technical_500_response(request, *exc_info)
[Thu Apr 11 14:14:34.414018 2019] [wsgi:error] [pid 17744:tid 139660747806464] [remote 66.249.65.126:40768]   File "/home/kibblerz/pyenv/pyenv/lib/python3.5/site-packages/django/views/debug.py", line 94, in technical_500_response
[Thu Apr 11 14:14:34.414024 2019] [wsgi:error] [pid 17744:tid 139660747806464] [remote 66.249.65.126:40768]     html = reporter.get_traceback_html()
[Thu Apr 11 14:14:34.414034 2019] [wsgi:error] [pid 17744:tid 139660747806464] [remote 66.249.65.126:40768]   File "/home/kibblerz/pyenv/pyenv/lib/python3.5/site-packages/django/views/debug.py", line 332, in get_traceback_html
[Thu Apr 11 14:14:34.414040 2019] [wsgi:error] [pid 17744:tid 139660747806464] [remote 66.249.65.126:40768]     t = DEBUG_ENGINE.from_string(fh.read())
[Thu Apr 11 14:14:34.414050 2019] [wsgi:error] [pid 17744:tid 139660747806464] [remote 66.249.65.126:40768]   File "/home/kibblerz/pyenv/pyenv/lib/python3.5/encodings/ascii.py", line 26, in decode
[Thu Apr 11 14:14:34.414056 2019] [wsgi:error] [pid 17744:tid 139660747806464] [remote 66.249.65.126:40768]     return codecs.ascii_decode(input, self.errors)[0]
[Thu Apr 11 14:14:34.414073 2019] [wsgi:error] [pid 17744:tid 139660747806464] [remote 66.249.65.126:40768] UnicodeDecodeError: 'ascii' codec can't decode byte 0xe2 in position 9735: ordinal not in range(128)
[Thu Apr 11 14:14:34.414087 2019] [wsgi:error] [pid 17744:tid 139660747806464] [remote 66.249.65.126:40768] 
[Thu Apr 11 14:14:34.414093 2019] [wsgi:error] [pid 17744:tid 139660747806464] [remote 66.249.65.126:40768] During handling of the above exception, another exception occurred:
[Thu Apr 11 14:14:34.414098 2019] [wsgi:error] [pid 17744:tid 139660747806464] [remote 66.249.65.126:40768] 
[Thu Apr 11 14:14:34.414108 2019] [wsgi:error] [pid 17744:tid 139660747806464] [remote 66.249.65.126:40768] Traceback (most recent call last):
[Thu Apr 11 14:14:34.414148 2019] [wsgi:error] [pid 17744:tid 139660747806464] [remote 66.249.65.126:40768]   File "/home/kibblerz/pyenv/pyenv/lib/python3.5/site-packages/django/core/handlers/wsgi.py", line 141, in __call__
[Thu Apr 11 14:14:34.414155 2019] [wsgi:error] [pid 17744:tid 139660747806464] [remote 66.249.65.126:40768]     response = self.get_response(request)
[Thu Apr 11 14:14:34.414166 2019] [wsgi:error] [pid 17744:tid 139660747806464] [remote 66.249.65.126:40768]   File "/home/kibblerz/pyenv/pyenv/lib/python3.5/site-packages/django/core/handlers/base.py", line 75, in get_response
[Thu Apr 11 14:14:34.414173 2019] [wsgi:error] [pid 17744:tid 139660747806464] [remote 66.249.65.126:40768]     response = self._middleware_chain(request)
[Thu Apr 11 14:14:34.414183 2019] [wsgi:error] [pid 17744:tid 139660747806464] [remote 66.249.65.126:40768]   File "/home/kibblerz/pyenv/pyenv/lib/python3.5/site-packages/django/core/handlers/exception.py", line 36, in inner
[Thu Apr 11 14:14:34.414189 2019] [wsgi:error] [pid 17744:tid 139660747806464] [remote 66.249.65.126:40768]     response = response_for_exception(request, exc)
[Thu Apr 11 14:14:34.414199 2019] [wsgi:error] [pid 17744:tid 139660747806464] [remote 66.249.65.126:40768]   File "/home/kibblerz/pyenv/pyenv/lib/python3.5/site-packages/django/core/handlers/exception.py", line 90, in response_for_exception
[Thu Apr 11 14:14:34.414210 2019] [wsgi:error] [pid 17744:tid 139660747806464] [remote 66.249.65.126:40768]     response = handle_uncaught_exception(request, get_resolver(get_urlconf()), sys.exc_info())
[Thu Apr 11 14:14:34.414221 2019] [wsgi:error] [pid 17744:tid 139660747806464] [remote 66.249.65.126:40768]   File "/home/kibblerz/pyenv/pyenv/lib/python3.5/site-packages/django/core/handlers/exception.py", line 125, in handle_uncaught_exception
[Thu Apr 11 14:14:34.414228 2019] [wsgi:error] [pid 17744:tid 139660747806464] [remote 66.249.65.126:40768]     return debug.technical_500_response(request, *exc_info)
[Thu Apr 11 14:14:34.414238 2019] [wsgi:error] [pid 17744:tid 139660747806464] [remote 66.249.65.126:40768]   File "/home/kibblerz/pyenv/pyenv/lib/python3.5/site-packages/django/views/debug.py", line 94, in technical_500_response
[Thu Apr 11 14:14:34.414244 2019] [wsgi:error] [pid 17744:tid 139660747806464] [remote 66.249.65.126:40768]     html = reporter.get_traceback_html()
[Thu Apr 11 14:14:34.414255 2019] [wsgi:error] [pid 17744:tid 139660747806464] [remote 66.249.65.126:40768]   File "/home/kibblerz/pyenv/pyenv/lib/python3.5/site-packages/django/views/debug.py", line 332, in get_traceback_html
[Thu Apr 11 14:14:34.414261 2019] [wsgi:error] [pid 17744:tid 139660747806464] [remote 66.249.65.126:40768]     t = DEBUG_ENGINE.from_string(fh.read())
[Thu Apr 11 14:14:34.414271 2019] [wsgi:error] [pid 17744:tid 139660747806464] [remote 66.249.65.126:40768]   File "/home/kibblerz/pyenv/pyenv/lib/python3.5/encodings/ascii.py", line 26, in decode
[Thu Apr 11 14:14:34.414277 2019] [wsgi:error] [pid 17744:tid 139660747806464] [remote 66.249.65.126:40768]     return codecs.ascii_decode(input, self.errors)[0]
[Thu Apr 11 14:14:34.414293 2019] [wsgi:error] [pid 17744:tid 139660747806464] [remote 66.249.65.126:40768] UnicodeDecodeError: 'ascii' codec can't decode byte 0xe2 in position 9735: ordinal not in range(128)
[Thu Apr 11 14:15:51.251886 2019] [wsgi:error] [pid 17744:tid 139660747806464] [remote 107.9.188.191:57155] mod_wsgi (pid=17744): Exception occurred processing WSGI script '/var/www/portfolio/back/wsgi.py'.
[Thu Apr 11 14:15:51.252837 2019] [wsgi:error] [pid 17744:tid 139660747806464] [remote 107.9.188.191:57155] Traceback (most recent call last):
[Thu Apr 11 14:15:51.252888 2019] [wsgi:error] [pid 17744:tid 139660747806464] [remote 107.9.188.191:57155]   File "/home/kibblerz/pyenv/pyenv/lib/python3.5/site-packages/django/core/handlers/exception.py", line 34, in inner
[Thu Apr 11 14:15:51.252898 2019] [wsgi:error] [pid 17744:tid 139660747806464] [remote 107.9.188.191:57155]     response = get_response(request)
[Thu Apr 11 14:15:51.252912 2019] [wsgi:error] [pid 17744:tid 139660747806464] [remote 107.9.188.191:57155]   File "/home/kibblerz/pyenv/pyenv/lib/python3.5/site-packages/django/core/handlers/base.py", line 115, in _get_response
[Thu Apr 11 14:15:51.252920 2019] [wsgi:error] [pid 17744:tid 139660747806464] [remote 107.9.188.191:57155]     response = self.process_exception_by_middleware(e, request)
[Thu Apr 11 14:15:51.252940 2019] [wsgi:error] [pid 17744:tid 139660747806464] [remote 107.9.188.191:57155]   File "/home/kibblerz/pyenv/pyenv/lib/python3.5/site-packages/django/core/handlers/base.py", line 113, in _get_response
[Thu Apr 11 14:15:51.252947 2019] [wsgi:error] [pid 17744:tid 139660747806464] [remote 107.9.188.191:57155]     response = wrapped_callback(request, *callback_args, **callback_kwargs)
[Thu Apr 11 14:15:51.252959 2019] [wsgi:error] [pid 17744:tid 139660747806464] [remote 107.9.188.191:57155]   File "/var/www/portfolio/main/views.py", line 12, in contact
[Thu Apr 11 14:15:51.252966 2019] [wsgi:error] [pid 17744:tid 139660747806464] [remote 107.9.188.191:57155]     content = json.loads(request.body)
[Thu Apr 11 14:15:51.252978 2019] [wsgi:error] [pid 17744:tid 139660747806464] [remote 107.9.188.191:57155]   File "/usr/lib/python3.5/json/__init__.py", line 312, in loads
[Thu Apr 11 14:15:51.253005 2019] [wsgi:error] [pid 17744:tid 139660747806464] [remote 107.9.188.191:57155]     s.__class__.__name__))
[Thu Apr 11 14:15:51.253029 2019] [wsgi:error] [pid 17744:tid 139660747806464] [remote 107.9.188.191:57155] TypeError: the JSON object must be str, not 'bytes'
[Thu Apr 11 14:15:51.253045 2019] [wsgi:error] [pid 17744:tid 139660747806464] [remote 107.9.188.191:57155] 
[Thu Apr 11 14:15:51.253051 2019] [wsgi:error] [pid 17744:tid 139660747806464] [remote 107.9.188.191:57155] During handling of the above exception, another exception occurred:
[Thu Apr 11 14:15:51.253057 2019] [wsgi:error] [pid 17744:tid 139660747806464] [remote 107.9.188.191:57155] 
[Thu Apr 11 14:15:51.253068 2019] [wsgi:error] [pid 17744:tid 139660747806464] [remote 107.9.188.191:57155] Traceback (most recent call last):
[Thu Apr 11 14:15:51.253112 2019] [wsgi:error] [pid 17744:tid 139660747806464] [remote 107.9.188.191:57155]   File "/home/kibblerz/pyenv/pyenv/lib/python3.5/site-packages/django/core/handlers/exception.py", line 34, in inner
[Thu Apr 11 14:15:51.253120 2019] [wsgi:error] [pid 17744:tid 139660747806464] [remote 107.9.188.191:57155]     response = get_response(request)
[Thu Apr 11 14:15:51.253132 2019] [wsgi:error] [pid 17744:tid 139660747806464] [remote 107.9.188.191:57155]   File "/home/kibblerz/pyenv/pyenv/lib/python3.5/site-packages/django/utils/deprecation.py", line 94, in __call__
[Thu Apr 11 14:15:51.253139 2019] [wsgi:error] [pid 17744:tid 139660747806464] [remote 107.9.188.191:57155]     response = response or self.get_response(request)
[Thu Apr 11 14:15:51.253150 2019] [wsgi:error] [pid 17744:tid 139660747806464] [remote 107.9.188.191:57155]   File "/home/kibblerz/pyenv/pyenv/lib/python3.5/site-packages/django/core/handlers/exception.py", line 36, in inner
[Thu Apr 11 14:15:51.253156 2019] [wsgi:error] [pid 17744:tid 139660747806464] [remote 107.9.188.191:57155]     response = response_for_exception(request, exc)
[Thu Apr 11 14:15:51.253168 2019] [wsgi:error] [pid 17744:tid 139660747806464] [remote 107.9.188.191:57155]   File "/home/kibblerz/pyenv/pyenv/lib/python3.5/site-packages/django/core/handlers/exception.py", line 90, in response_for_exception
[Thu Apr 11 14:15:51.253174 2019] [wsgi:error] [pid 17744:tid 139660747806464] [remote 107.9.188.191:57155]     response = handle_uncaught_exception(request, get_resolver(get_urlconf()), sys.exc_info())
[Thu Apr 11 14:15:51.253186 2019] [wsgi:error] [pid 17744:tid 139660747806464] [remote 107.9.188.191:57155]   File "/home/kibblerz/pyenv/pyenv/lib/python3.5/site-packages/django/core/handlers/exception.py", line 125, in handle_uncaught_exception
[Thu Apr 11 14:15:51.253192 2019] [wsgi:error] [pid 17744:tid 139660747806464] [remote 107.9.188.191:57155]     return debug.technical_500_response(request, *exc_info)
[Thu Apr 11 14:15:51.253204 2019] [wsgi:error] [pid 17744:tid 139660747806464] [remote 107.9.188.191:57155]   File "/home/kibblerz/pyenv/pyenv/lib/python3.5/site-packages/django/views/debug.py", line 94, in technical_500_response
[Thu Apr 11 14:15:51.253210 2019] [wsgi:error] [pid 17744:tid 139660747806464] [remote 107.9.188.191:57155]     html = reporter.get_traceback_html()
[Thu Apr 11 14:15:51.253221 2019] [wsgi:error] [pid 17744:tid 139660747806464] [remote 107.9.188.191:57155]   File "/home/kibblerz/pyenv/pyenv/lib/python3.5/site-packages/django/views/debug.py", line 332, in get_traceback_html
[Thu Apr 11 14:15:51.253228 2019] [wsgi:error] [pid 17744:tid 139660747806464] [remote 107.9.188.191:57155]     t = DEBUG_ENGINE.from_string(fh.read())
[Thu Apr 11 14:15:51.253239 2019] [wsgi:error] [pid 17744:tid 139660747806464] [remote 107.9.188.191:57155]   File "/home/kibblerz/pyenv/pyenv/lib/python3.5/encodings/ascii.py", line 26, in decode
[Thu Apr 11 14:15:51.253245 2019] [wsgi:error] [pid 17744:tid 139660747806464] [remote 107.9.188.191:57155]     return codecs.ascii_decode(input, self.errors)[0]
[Thu Apr 11 14:15:51.253263 2019] [wsgi:error] [pid 17744:tid 139660747806464] [remote 107.9.188.191:57155] UnicodeDecodeError: 'ascii' codec can't decode byte 0xe2 in position 9735: ordinal not in range(128)
[Thu Apr 11 14:15:51.253285 2019] [wsgi:error] [pid 17744:tid 139660747806464] [remote 107.9.188.191:57155] 
[Thu Apr 11 14:15:51.253291 2019] [wsgi:error] [pid 17744:tid 139660747806464] [remote 107.9.188.191:57155] During handling of the above exception, another exception occurred:
[Thu Apr 11 14:15:51.253297 2019] [wsgi:error] [pid 17744:tid 139660747806464] [remote 107.9.188.191:57155] 
[Thu Apr 11 14:15:51.253308 2019] [wsgi:error] [pid 17744:tid 139660747806464] [remote 107.9.188.191:57155] Traceback (most recent call last):
[Thu Apr 11 14:15:51.253350 2019] [wsgi:error] [pid 17744:tid 139660747806464] [remote 107.9.188.191:57155]   File "/home/kibblerz/pyenv/pyenv/lib/python3.5/site-packages/django/core/handlers/exception.py", line 34, in inner
[Thu Apr 11 14:15:51.253358 2019] [wsgi:error] [pid 17744:tid 139660747806464] [remote 107.9.188.191:57155]     response = get_response(request)
[Thu Apr 11 14:15:51.253369 2019] [wsgi:error] [pid 17744:tid 139660747806464] [remote 107.9.188.191:57155]   File "/home/kibblerz/pyenv/pyenv/lib/python3.5/site-packages/django/utils/deprecation.py", line 94, in __call__
[Thu Apr 11 14:15:51.253376 2019] [wsgi:error] [pid 17744:tid 139660747806464] [remote 107.9.188.191:57155]     response = response or self.get_response(request)
[Thu Apr 11 14:15:51.253387 2019] [wsgi:error] [pid 17744:tid 139660747806464] [remote 107.9.188.191:57155]   File "/home/kibblerz/pyenv/pyenv/lib/python3.5/site-packages/django/core/handlers/exception.py", line 36, in inner
[Thu Apr 11 14:15:51.253393 2019] [wsgi:error] [pid 17744:tid 139660747806464] [remote 107.9.188.191:57155]     response = response_for_exception(request, exc)
[Thu Apr 11 14:15:51.253404 2019] [wsgi:error] [pid 17744:tid 139660747806464] [remote 107.9.188.191:57155]   File "/home/kibblerz/pyenv/pyenv/lib/python3.5/site-packages/django/core/handlers/exception.py", line 90, in response_for_exception
[Thu Apr 11 14:15:51.253411 2019] [wsgi:error] [pid 17744:tid 139660747806464] [remote 107.9.188.191:57155]     response = handle_uncaught_exception(request, get_resolver(get_urlconf()), sys.exc_info())
[Thu Apr 11 14:15:51.253422 2019] [wsgi:error] [pid 17744:tid 139660747806464] [remote 107.9.188.191:57155]   File "/home/kibblerz/pyenv/pyenv/lib/python3.5/site-packages/django/core/handlers/exception.py", line 125, in handle_uncaught_exception
[Thu Apr 11 14:15:51.253429 2019] [wsgi:error] [pid 17744:tid 139660747806464] [remote 107.9.188.191:57155]     return debug.technical_500_response(request, *exc_info)
[Thu Apr 11 14:15:51.253440 2019] [wsgi:error] [pid 17744:tid 139660747806464] [remote 107.9.188.191:57155]   File "/home/kibblerz/pyenv/pyenv/lib/python3.5/site-packages/django/views/debug.py", line 94, in technical_500_response
[Thu Apr 11 14:15:51.253446 2019] [wsgi:error] [pid 17744:tid 139660747806464] [remote 107.9.188.191:57155]     html = reporter.get_traceback_html()
[Thu Apr 11 14:15:51.253457 2019] [wsgi:error] [pid 17744:tid 139660747806464] [remote 107.9.188.191:57155]   File "/home/kibblerz/pyenv/pyenv/lib/python3.5/site-packages/django/views/debug.py", line 332, in get_traceback_html
[Thu Apr 11 14:15:51.253464 2019] [wsgi:error] [pid 17744:tid 139660747806464] [remote 107.9.188.191:57155]     t = DEBUG_ENGINE.from_string(fh.read())
[Thu Apr 11 14:15:51.253474 2019] [wsgi:error] [pid 17744:tid 139660747806464] [remote 107.9.188.191:57155]   File "/home/kibblerz/pyenv/pyenv/lib/python3.5/encodings/ascii.py", line 26, in decode
[Thu Apr 11 14:15:51.253481 2019] [wsgi:error] [pid 17744:tid 139660747806464] [remote 107.9.188.191:57155]     return codecs.ascii_decode(input, self.errors)[0]
[Thu Apr 11 14:15:51.253498 2019] [wsgi:error] [pid 17744:tid 139660747806464] [remote 107.9.188.191:57155] UnicodeDecodeError: 'ascii' codec can't decode byte 0xe2 in position 9735: ordinal not in range(128)
[Thu Apr 11 14:15:51.253512 2019] [wsgi:error] [pid 17744:tid 139660747806464] [remote 107.9.188.191:57155] 
[Thu Apr 11 14:15:51.253519 2019] [wsgi:error] [pid 17744:tid 139660747806464] [remote 107.9.188.191:57155] During handling of the above exception, another exception occurred:
[Thu Apr 11 14:15:51.253529 2019] [wsgi:error] [pid 17744:tid 139660747806464] [remote 107.9.188.191:57155] 
[Thu Apr 11 14:15:51.253541 2019] [wsgi:error] [pid 17744:tid 139660747806464] [remote 107.9.188.191:57155] Traceback (most recent call last):
[Thu Apr 11 14:15:51.253583 2019] [wsgi:error] [pid 17744:tid 139660747806464] [remote 107.9.188.191:57155]   File "/home/kibblerz/pyenv/pyenv/lib/python3.5/site-packages/django/core/handlers/exception.py", line 34, in inner
[Thu Apr 11 14:15:51.253591 2019] [wsgi:error] [pid 17744:tid 139660747806464] [remote 107.9.188.191:57155]     response = get_response(request)
[Thu Apr 11 14:15:51.253602 2019] [wsgi:error] [pid 17744:tid 139660747806464] [remote 107.9.188.191:57155]   File "/home/kibblerz/pyenv/pyenv/lib/python3.5/site-packages/django/utils/deprecation.py", line 94, in __call__
[Thu Apr 11 14:15:51.253609 2019] [wsgi:error] [pid 17744:tid 139660747806464] [remote 107.9.188.191:57155]     response = response or self.get_response(request)
[Thu Apr 11 14:15:51.253619 2019] [wsgi:error] [pid 17744:tid 139660747806464] [remote 107.9.188.191:57155]   File "/home/kibblerz/pyenv/pyenv/lib/python3.5/site-packages/django/core/handlers/exception.py", line 36, in inner
[Thu Apr 11 14:15:51.253626 2019] [wsgi:error] [pid 17744:tid 139660747806464] [remote 107.9.188.191:57155]     response = response_for_exception(request, exc)
[Thu Apr 11 14:15:51.253651 2019] [wsgi:error] [pid 17744:tid 139660747806464] [remote 107.9.188.191:57155]   File "/home/kibblerz/pyenv/pyenv/lib/python3.5/site-packages/django/core/handlers/exception.py", line 90, in response_for_exception
[Thu Apr 11 14:15:51.253658 2019] [wsgi:error] [pid 17744:tid 139660747806464] [remote 107.9.188.191:57155]     response = handle_uncaught_exception(request, get_resolver(get_urlconf()), sys.exc_info())
[Thu Apr 11 14:15:51.253669 2019] [wsgi:error] [pid 17744:tid 139660747806464] [remote 107.9.188.191:57155]   File "/home/kibblerz/pyenv/pyenv/lib/python3.5/site-packages/django/core/handlers/exception.py", line 125, in handle_uncaught_exception
[Thu Apr 11 14:15:51.253679 2019] [wsgi:error] [pid 17744:tid 139660747806464] [remote 107.9.188.191:57155]     return debug.technical_500_response(request, *exc_info)
[Thu Apr 11 14:15:51.253690 2019] [wsgi:error] [pid 17744:tid 139660747806464] [remote 107.9.188.191:57155]   File "/home/kibblerz/pyenv/pyenv/lib/python3.5/site-packages/django/views/debug.py", line 94, in technical_500_response
[Thu Apr 11 14:15:51.253696 2019] [wsgi:error] [pid 17744:tid 139660747806464] [remote 107.9.188.191:57155]     html = reporter.get_traceback_html()
[Thu Apr 11 14:15:51.253707 2019] [wsgi:error] [pid 17744:tid 139660747806464] [remote 107.9.188.191:57155]   File "/home/kibblerz/pyenv/pyenv/lib/python3.5/site-packages/django/views/debug.py", line 332, in get_traceback_html
[Thu Apr 11 14:15:51.253713 2019] [wsgi:error] [pid 17744:tid 139660747806464] [remote 107.9.188.191:57155]     t = DEBUG_ENGINE.from_string(fh.read())
[Thu Apr 11 14:15:51.253724 2019] [wsgi:error] [pid 17744:tid 139660747806464] [remote 107.9.188.191:57155]   File "/home/kibblerz/pyenv/pyenv/lib/python3.5/encodings/ascii.py", line 26, in decode
[Thu Apr 11 14:15:51.253730 2019] [wsgi:error] [pid 17744:tid 139660747806464] [remote 107.9.188.191:57155]     return codecs.ascii_decode(input, self.errors)[0]
[Thu Apr 11 14:15:51.253748 2019] [wsgi:error] [pid 17744:tid 139660747806464] [remote 107.9.188.191:57155] UnicodeDecodeError: 'ascii' codec can't decode byte 0xe2 in position 9735: ordinal not in range(128)
[Thu Apr 11 14:15:51.253763 2019] [wsgi:error] [pid 17744:tid 139660747806464] [remote 107.9.188.191:57155] 
[Thu Apr 11 14:15:51.253769 2019] [wsgi:error] [pid 17744:tid 139660747806464] [remote 107.9.188.191:57155] During handling of the above exception, another exception occurred:
[Thu Apr 11 14:15:51.253774 2019] [wsgi:error] [pid 17744:tid 139660747806464] [remote 107.9.188.191:57155] 
[Thu Apr 11 14:15:51.253791 2019] [wsgi:error] [pid 17744:tid 139660747806464] [remote 107.9.188.191:57155] Traceback (most recent call last):
[Thu Apr 11 14:15:51.253834 2019] [wsgi:error] [pid 17744:tid 139660747806464] [remote 107.9.188.191:57155]   File "/home/kibblerz/pyenv/pyenv/lib/python3.5/site-packages/django/core/handlers/exception.py", line 34, in inner
[Thu Apr 11 14:15:51.253842 2019] [wsgi:error] [pid 17744:tid 139660747806464] [remote 107.9.188.191:57155]     response = get_response(request)
[Thu Apr 11 14:15:51.253853 2019] [wsgi:error] [pid 17744:tid 139660747806464] [remote 107.9.188.191:57155]   File "/home/kibblerz/pyenv/pyenv/lib/python3.5/site-packages/django/utils/deprecation.py", line 94, in __call__
[Thu Apr 11 14:15:51.253860 2019] [wsgi:error] [pid 17744:tid 139660747806464] [remote 107.9.188.191:57155]     response = response or self.get_response(request)
[Thu Apr 11 14:15:51.253871 2019] [wsgi:error] [pid 17744:tid 139660747806464] [remote 107.9.188.191:57155]   File "/home/kibblerz/pyenv/pyenv/lib/python3.5/site-packages/django/core/handlers/exception.py", line 36, in inner
[Thu Apr 11 14:15:51.253877 2019] [wsgi:error] [pid 17744:tid 139660747806464] [remote 107.9.188.191:57155]     response = response_for_exception(request, exc)
[Thu Apr 11 14:15:51.253888 2019] [wsgi:error] [pid 17744:tid 139660747806464] [remote 107.9.188.191:57155]   File "/home/kibblerz/pyenv/pyenv/lib/python3.5/site-packages/django/core/handlers/exception.py", line 90, in response_for_exception
[Thu Apr 11 14:15:51.253894 2019] [wsgi:error] [pid 17744:tid 139660747806464] [remote 107.9.188.191:57155]     response = handle_uncaught_exception(request, get_resolver(get_urlconf()), sys.exc_info())
[Thu Apr 11 14:15:51.253905 2019] [wsgi:error] [pid 17744:tid 139660747806464] [remote 107.9.188.191:57155]   File "/home/kibblerz/pyenv/pyenv/lib/python3.5/site-packages/django/core/handlers/exception.py", line 125, in handle_uncaught_exception
[Thu Apr 11 14:15:51.253912 2019] [wsgi:error] [pid 17744:tid 139660747806464] [remote 107.9.188.191:57155]     return debug.technical_500_response(request, *exc_info)
[Thu Apr 11 14:15:51.253923 2019] [wsgi:error] [pid 17744:tid 139660747806464] [remote 107.9.188.191:57155]   File "/home/kibblerz/pyenv/pyenv/lib/python3.5/site-packages/django/views/debug.py", line 94, in technical_500_response
[Thu Apr 11 14:15:51.253930 2019] [wsgi:error] [pid 17744:tid 139660747806464] [remote 107.9.188.191:57155]     html = reporter.get_traceback_html()
[Thu Apr 11 14:15:51.253940 2019] [wsgi:error] [pid 17744:tid 139660747806464] [remote 107.9.188.191:57155]   File "/home/kibblerz/pyenv/pyenv/lib/python3.5/site-packages/django/views/debug.py", line 332, in get_traceback_html
[Thu Apr 11 14:15:51.253947 2019] [wsgi:error] [pid 17744:tid 139660747806464] [remote 107.9.188.191:57155]     t = DEBUG_ENGINE.from_string(fh.read())
[Thu Apr 11 14:15:51.253958 2019] [wsgi:error] [pid 17744:tid 139660747806464] [remote 107.9.188.191:57155]   File "/home/kibblerz/pyenv/pyenv/lib/python3.5/encodings/ascii.py", line 26, in decode
[Thu Apr 11 14:15:51.253964 2019] [wsgi:error] [pid 17744:tid 139660747806464] [remote 107.9.188.191:57155]     return codecs.ascii_decode(input, self.errors)[0]
[Thu Apr 11 14:15:51.253981 2019] [wsgi:error] [pid 17744:tid 139660747806464] [remote 107.9.188.191:57155] UnicodeDecodeError: 'ascii' codec can't decode byte 0xe2 in position 9735: ordinal not in range(128)
[Thu Apr 11 14:15:51.253995 2019] [wsgi:error] [pid 17744:tid 139660747806464] [remote 107.9.188.191:57155] 
[Thu Apr 11 14:15:51.254002 2019] [wsgi:error] [pid 17744:tid 139660747806464] [remote 107.9.188.191:57155] During handling of the above exception, another exception occurred:
[Thu Apr 11 14:15:51.254007 2019] [wsgi:error] [pid 17744:tid 139660747806464] [remote 107.9.188.191:57155] 
[Thu Apr 11 14:15:51.254018 2019] [wsgi:error] [pid 17744:tid 139660747806464] [remote 107.9.188.191:57155] Traceback (most recent call last):
[Thu Apr 11 14:15:51.254062 2019] [wsgi:error] [pid 17744:tid 139660747806464] [remote 107.9.188.191:57155]   File "/home/kibblerz/pyenv/pyenv/lib/python3.5/site-packages/django/core/handlers/exception.py", line 34, in inner
[Thu Apr 11 14:15:51.254075 2019] [wsgi:error] [pid 17744:tid 139660747806464] [remote 107.9.188.191:57155]     response = get_response(request)
[Thu Apr 11 14:15:51.254087 2019] [wsgi:error] [pid 17744:tid 139660747806464] [remote 107.9.188.191:57155]   File "/home/kibblerz/pyenv/pyenv/lib/python3.5/site-packages/django/utils/deprecation.py", line 94, in __call__
[Thu Apr 11 14:15:51.254093 2019] [wsgi:error] [pid 17744:tid 139660747806464] [remote 107.9.188.191:57155]     response = response or self.get_response(request)
[Thu Apr 11 14:15:51.254104 2019] [wsgi:error] [pid 17744:tid 139660747806464] [remote 107.9.188.191:57155]   File "/home/kibblerz/pyenv/pyenv/lib/python3.5/site-packages/django/core/handlers/exception.py", line 36, in inner
[Thu Apr 11 14:15:51.254110 2019] [wsgi:error] [pid 17744:tid 139660747806464] [remote 107.9.188.191:57155]     response = response_for_exception(request, exc)
[Thu Apr 11 14:15:51.254121 2019] [wsgi:error] [pid 17744:tid 139660747806464] [remote 107.9.188.191:57155]   File "/home/kibblerz/pyenv/pyenv/lib/python3.5/site-packages/django/core/handlers/exception.py", line 90, in response_for_exception
[Thu Apr 11 14:15:51.254128 2019] [wsgi:error] [pid 17744:tid 139660747806464] [remote 107.9.188.191:57155]     response = handle_uncaught_exception(request, get_resolver(get_urlconf()), sys.exc_info())
[Thu Apr 11 14:15:51.254138 2019] [wsgi:error] [pid 17744:tid 139660747806464] [remote 107.9.188.191:57155]   File "/home/kibblerz/pyenv/pyenv/lib/python3.5/site-packages/django/core/handlers/exception.py", line 125, in handle_uncaught_exception
[Thu Apr 11 14:15:51.254145 2019] [wsgi:error] [pid 17744:tid 139660747806464] [remote 107.9.188.191:57155]     return debug.technical_500_response(request, *exc_info)
[Thu Apr 11 14:15:51.254156 2019] [wsgi:error] [pid 17744:tid 139660747806464] [remote 107.9.188.191:57155]   File "/home/kibblerz/pyenv/pyenv/lib/python3.5/site-packages/django/views/debug.py", line 94, in technical_500_response
[Thu Apr 11 14:15:51.254162 2019] [wsgi:error] [pid 17744:tid 139660747806464] [remote 107.9.188.191:57155]     html = reporter.get_traceback_html()
[Thu Apr 11 14:15:51.254173 2019] [wsgi:error] [pid 17744:tid 139660747806464] [remote 107.9.188.191:57155]   File "/home/kibblerz/pyenv/pyenv/lib/python3.5/site-packages/django/views/debug.py", line 332, in get_traceback_html
[Thu Apr 11 14:15:51.254180 2019] [wsgi:error] [pid 17744:tid 139660747806464] [remote 107.9.188.191:57155]     t = DEBUG_ENGINE.from_string(fh.read())
[Thu Apr 11 14:15:51.254190 2019] [wsgi:error] [pid 17744:tid 139660747806464] [remote 107.9.188.191:57155]   File "/home/kibblerz/pyenv/pyenv/lib/python3.5/encodings/ascii.py", line 26, in decode
[Thu Apr 11 14:15:51.254197 2019] [wsgi:error] [pid 17744:tid 139660747806464] [remote 107.9.188.191:57155]     return codecs.ascii_decode(input, self.errors)[0]
[Thu Apr 11 14:15:51.254214 2019] [wsgi:error] [pid 17744:tid 139660747806464] [remote 107.9.188.191:57155] UnicodeDecodeError: 'ascii' codec can't decode byte 0xe2 in position 9735: ordinal not in range(128)
[Thu Apr 11 14:15:51.254228 2019] [wsgi:error] [pid 17744:tid 139660747806464] [remote 107.9.188.191:57155] 
[Thu Apr 11 14:15:51.254234 2019] [wsgi:error] [pid 17744:tid 139660747806464] [remote 107.9.188.191:57155] During handling of the above exception, another exception occurred:
[Thu Apr 11 14:15:51.254239 2019] [wsgi:error] [pid 17744:tid 139660747806464] [remote 107.9.188.191:57155] 
[Thu Apr 11 14:15:51.254250 2019] [wsgi:error] [pid 17744:tid 139660747806464] [remote 107.9.188.191:57155] Traceback (most recent call last):
[Thu Apr 11 14:15:51.254291 2019] [wsgi:error] [pid 17744:tid 139660747806464] [remote 107.9.188.191:57155]   File "/home/kibblerz/pyenv/pyenv/lib/python3.5/site-packages/django/core/handlers/exception.py", line 34, in inner
[Thu Apr 11 14:15:51.254299 2019] [wsgi:error] [pid 17744:tid 139660747806464] [remote 107.9.188.191:57155]     response = get_response(request)
[Thu Apr 11 14:15:51.254315 2019] [wsgi:error] [pid 17744:tid 139660747806464] [remote 107.9.188.191:57155]   File "/home/kibblerz/pyenv/pyenv/lib/python3.5/site-packages/django/utils/deprecation.py", line 94, in __call__
[Thu Apr 11 14:15:51.254322 2019] [wsgi:error] [pid 17744:tid 139660747806464] [remote 107.9.188.191:57155]     response = response or self.get_response(request)
[Thu Apr 11 14:15:51.254333 2019] [wsgi:error] [pid 17744:tid 139660747806464] [remote 107.9.188.191:57155]   File "/home/kibblerz/pyenv/pyenv/lib/python3.5/site-packages/django/core/handlers/exception.py", line 36, in inner
[Thu Apr 11 14:15:51.254339 2019] [wsgi:error] [pid 17744:tid 139660747806464] [remote 107.9.188.191:57155]     response = response_for_exception(request, exc)
[Thu Apr 11 14:15:51.254350 2019] [wsgi:error] [pid 17744:tid 139660747806464] [remote 107.9.188.191:57155]   File "/home/kibblerz/pyenv/pyenv/lib/python3.5/site-packages/django/core/handlers/exception.py", line 90, in response_for_exception
[Thu Apr 11 14:15:51.254356 2019] [wsgi:error] [pid 17744:tid 139660747806464] [remote 107.9.188.191:57155]     response = handle_uncaught_exception(request, get_resolver(get_urlconf()), sys.exc_info())
[Thu Apr 11 14:15:51.254367 2019] [wsgi:error] [pid 17744:tid 139660747806464] [remote 107.9.188.191:57155]   File "/home/kibblerz/pyenv/pyenv/lib/python3.5/site-packages/django/core/handlers/exception.py", line 125, in handle_uncaught_exception
[Thu Apr 11 14:15:51.254374 2019] [wsgi:error] [pid 17744:tid 139660747806464] [remote 107.9.188.191:57155]     return debug.technical_500_response(request, *exc_info)
[Thu Apr 11 14:15:51.254385 2019] [wsgi:error] [pid 17744:tid 139660747806464] [remote 107.9.188.191:57155]   File "/home/kibblerz/pyenv/pyenv/lib/python3.5/site-packages/django/views/debug.py", line 94, in technical_500_response
[Thu Apr 11 14:15:51.254391 2019] [wsgi:error] [pid 17744:tid 139660747806464] [remote 107.9.188.191:57155]     html = reporter.get_traceback_html()
[Thu Apr 11 14:15:51.254402 2019] [wsgi:error] [pid 17744:tid 139660747806464] [remote 107.9.188.191:57155]   File "/home/kibblerz/pyenv/pyenv/lib/python3.5/site-packages/django/views/debug.py", line 332, in get_traceback_html
[Thu Apr 11 14:15:51.254408 2019] [wsgi:error] [pid 17744:tid 139660747806464] [remote 107.9.188.191:57155]     t = DEBUG_ENGINE.from_string(fh.read())
[Thu Apr 11 14:15:51.254419 2019] [wsgi:error] [pid 17744:tid 139660747806464] [remote 107.9.188.191:57155]   File "/home/kibblerz/pyenv/pyenv/lib/python3.5/encodings/ascii.py", line 26, in decode
[Thu Apr 11 14:15:51.254425 2019] [wsgi:error] [pid 17744:tid 139660747806464] [remote 107.9.188.191:57155]     return codecs.ascii_decode(input, self.errors)[0]
[Thu Apr 11 14:15:51.254442 2019] [wsgi:error] [pid 17744:tid 139660747806464] [remote 107.9.188.191:57155] UnicodeDecodeError: 'ascii' codec can't decode byte 0xe2 in position 9735: ordinal not in range(128)
[Thu Apr 11 14:15:51.254456 2019] [wsgi:error] [pid 17744:tid 139660747806464] [remote 107.9.188.191:57155] 
[Thu Apr 11 14:15:51.254462 2019] [wsgi:error] [pid 17744:tid 139660747806464] [remote 107.9.188.191:57155] During handling of the above exception, another exception occurred:
[Thu Apr 11 14:15:51.254467 2019] [wsgi:error] [pid 17744:tid 139660747806464] [remote 107.9.188.191:57155] 
[Thu Apr 11 14:15:51.254478 2019] [wsgi:error] [pid 17744:tid 139660747806464] [remote 107.9.188.191:57155] Traceback (most recent call last):
[Thu Apr 11 14:15:51.254519 2019] [wsgi:error] [pid 17744:tid 139660747806464] [remote 107.9.188.191:57155]   File "/home/kibblerz/pyenv/pyenv/lib/python3.5/site-packages/django/core/handlers/exception.py", line 34, in inner
[Thu Apr 11 14:15:51.254527 2019] [wsgi:error] [pid 17744:tid 139660747806464] [remote 107.9.188.191:57155]     response = get_response(request)
[Thu Apr 11 14:15:51.254538 2019] [wsgi:error] [pid 17744:tid 139660747806464] [remote 107.9.188.191:57155]   File "/home/kibblerz/pyenv/pyenv/lib/python3.5/site-packages/django/utils/deprecation.py", line 94, in __call__
[Thu Apr 11 14:15:51.254549 2019] [wsgi:error] [pid 17744:tid 139660747806464] [remote 107.9.188.191:57155]     response = response or self.get_response(request)
[Thu Apr 11 14:15:51.254560 2019] [wsgi:error] [pid 17744:tid 139660747806464] [remote 107.9.188.191:57155]   File "/home/kibblerz/pyenv/pyenv/lib/python3.5/site-packages/django/core/handlers/exception.py", line 36, in inner
[Thu Apr 11 14:15:51.254567 2019] [wsgi:error] [pid 17744:tid 139660747806464] [remote 107.9.188.191:57155]     response = response_for_exception(request, exc)
[Thu Apr 11 14:15:51.254578 2019] [wsgi:error] [pid 17744:tid 139660747806464] [remote 107.9.188.191:57155]   File "/home/kibblerz/pyenv/pyenv/lib/python3.5/site-packages/django/core/handlers/exception.py", line 90, in response_for_exception
[Thu Apr 11 14:15:51.254584 2019] [wsgi:error] [pid 17744:tid 139660747806464] [remote 107.9.188.191:57155]     response = handle_uncaught_exception(request, get_resolver(get_urlconf()), sys.exc_info())
[Thu Apr 11 14:15:51.254595 2019] [wsgi:error] [pid 17744:tid 139660747806464] [remote 107.9.188.191:57155]   File "/home/kibblerz/pyenv/pyenv/lib/python3.5/site-packages/django/core/handlers/exception.py", line 125, in handle_uncaught_exception
[Thu Apr 11 14:15:51.254605 2019] [wsgi:error] [pid 17744:tid 139660747806464] [remote 107.9.188.191:57155]     return debug.technical_500_response(request, *exc_info)
[Thu Apr 11 14:15:51.254616 2019] [wsgi:error] [pid 17744:tid 139660747806464] [remote 107.9.188.191:57155]   File "/home/kibblerz/pyenv/pyenv/lib/python3.5/site-packages/django/views/debug.py", line 94, in technical_500_response
[Thu Apr 11 14:15:51.254623 2019] [wsgi:error] [pid 17744:tid 139660747806464] [remote 107.9.188.191:57155]     html = reporter.get_traceback_html()
[Thu Apr 11 14:15:51.254647 2019] [wsgi:error] [pid 17744:tid 139660747806464] [remote 107.9.188.191:57155]   File "/home/kibblerz/pyenv/pyenv/lib/python3.5/site-packages/django/views/debug.py", line 332, in get_traceback_html
[Thu Apr 11 14:15:51.254655 2019] [wsgi:error] [pid 17744:tid 139660747806464] [remote 107.9.188.191:57155]     t = DEBUG_ENGINE.from_string(fh.read())
[Thu Apr 11 14:15:51.254665 2019] [wsgi:error] [pid 17744:tid 139660747806464] [remote 107.9.188.191:57155]   File "/home/kibblerz/pyenv/pyenv/lib/python3.5/encodings/ascii.py", line 26, in decode
[Thu Apr 11 14:15:51.254672 2019] [wsgi:error] [pid 17744:tid 139660747806464] [remote 107.9.188.191:57155]     return codecs.ascii_decode(input, self.errors)[0]
[Thu Apr 11 14:15:51.254689 2019] [wsgi:error] [pid 17744:tid 139660747806464] [remote 107.9.188.191:57155] UnicodeDecodeError: 'ascii' codec can't decode byte 0xe2 in position 9735: ordinal not in range(128)
[Thu Apr 11 14:15:51.254705 2019] [wsgi:error] [pid 17744:tid 139660747806464] [remote 107.9.188.191:57155] 
[Thu Apr 11 14:15:51.254711 2019] [wsgi:error] [pid 17744:tid 139660747806464] [remote 107.9.188.191:57155] During handling of the above exception, another exception occurred:
[Thu Apr 11 14:15:51.254716 2019] [wsgi:error] [pid 17744:tid 139660747806464] [remote 107.9.188.191:57155] 
[Thu Apr 11 14:15:51.254727 2019] [wsgi:error] [pid 17744:tid 139660747806464] [remote 107.9.188.191:57155] Traceback (most recent call last):
[Thu Apr 11 14:15:51.254768 2019] [wsgi:error] [pid 17744:tid 139660747806464] [remote 107.9.188.191:57155]   File "/home/kibblerz/pyenv/pyenv/lib/python3.5/site-packages/django/core/handlers/wsgi.py", line 141, in __call__
[Thu Apr 11 14:15:51.254776 2019] [wsgi:error] [pid 17744:tid 139660747806464] [remote 107.9.188.191:57155]     response = self.get_response(request)
[Thu Apr 11 14:15:51.254787 2019] [wsgi:error] [pid 17744:tid 139660747806464] [remote 107.9.188.191:57155]   File "/home/kibblerz/pyenv/pyenv/lib/python3.5/site-packages/django/core/handlers/base.py", line 75, in get_response
[Thu Apr 11 14:15:51.254794 2019] [wsgi:error] [pid 17744:tid 139660747806464] [remote 107.9.188.191:57155]     response = self._middleware_chain(request)
[Thu Apr 11 14:15:51.254804 2019] [wsgi:error] [pid 17744:tid 139660747806464] [remote 107.9.188.191:57155]   File "/home/kibblerz/pyenv/pyenv/lib/python3.5/site-packages/django/core/handlers/exception.py", line 36, in inner
[Thu Apr 11 14:15:51.254815 2019] [wsgi:error] [pid 17744:tid 139660747806464] [remote 107.9.188.191:57155]     response = response_for_exception(request, exc)
[Thu Apr 11 14:15:51.254827 2019] [wsgi:error] [pid 17744:tid 139660747806464] [remote 107.9.188.191:57155]   File "/home/kibblerz/pyenv/pyenv/lib/python3.5/site-packages/django/core/handlers/exception.py", line 90, in response_for_exception
[Thu Apr 11 14:15:51.254833 2019] [wsgi:error] [pid 17744:tid 139660747806464] [remote 107.9.188.191:57155]     response = handle_uncaught_exception(request, get_resolver(get_urlconf()), sys.exc_info())
[Thu Apr 11 14:15:51.254844 2019] [wsgi:error] [pid 17744:tid 139660747806464] [remote 107.9.188.191:57155]   File "/home/kibblerz/pyenv/pyenv/lib/python3.5/site-packages/django/core/handlers/exception.py", line 125, in handle_uncaught_exception
[Thu Apr 11 14:15:51.254850 2019] [wsgi:error] [pid 17744:tid 139660747806464] [remote 107.9.188.191:57155]     return debug.technical_500_response(request, *exc_info)
[Thu Apr 11 14:15:51.254861 2019] [wsgi:error] [pid 17744:tid 139660747806464] [remote 107.9.188.191:57155]   File "/home/kibblerz/pyenv/pyenv/lib/python3.5/site-packages/django/views/debug.py", line 94, in technical_500_response
[Thu Apr 11 14:15:51.254867 2019] [wsgi:error] [pid 17744:tid 139660747806464] [remote 107.9.188.191:57155]     html = reporter.get_traceback_html()
[Thu Apr 11 14:15:51.254878 2019] [wsgi:error] [pid 17744:tid 139660747806464] [remote 107.9.188.191:57155]   File "/home/kibblerz/pyenv/pyenv/lib/python3.5/site-packages/django/views/debug.py", line 332, in get_traceback_html
[Thu Apr 11 14:15:51.254884 2019] [wsgi:error] [pid 17744:tid 139660747806464] [remote 107.9.188.191:57155]     t = DEBUG_ENGINE.from_string(fh.read())
[Thu Apr 11 14:15:51.254894 2019] [wsgi:error] [pid 17744:tid 139660747806464] [remote 107.9.188.191:57155]   File "/home/kibblerz/pyenv/pyenv/lib/python3.5/encodings/ascii.py", line 26, in decode
[Thu Apr 11 14:15:51.254901 2019] [wsgi:error] [pid 17744:tid 139660747806464] [remote 107.9.188.191:57155]     return codecs.ascii_decode(input, self.errors)[0]
[Thu Apr 11 14:15:51.254918 2019] [wsgi:error] [pid 17744:tid 139660747806464] [remote 107.9.188.191:57155] UnicodeDecodeError: 'ascii' codec can't decode byte 0xe2 in position 9735: ordinal not in range(128)
[Thu Apr 11 14:15:58.056917 2019] [wsgi:error] [pid 17744:tid 139660600817408] Invalid HTTP_HOST header: 's97-74-233-104.secureserver.net'. You may need to add 's97-74-233-104.secureserver.net' to ALLOWED_HOSTS.
[Thu Apr 11 14:15:58.057514 2019] [wsgi:error] [pid 17744:tid 139660600817408] [remote 201.116.230.90:57411] mod_wsgi (pid=17744): Exception occurred processing WSGI script '/var/www/portfolio/back/wsgi.py'.
[Thu Apr 11 14:15:58.057988 2019] [wsgi:error] [pid 17744:tid 139660600817408] [remote 201.116.230.90:57411] Traceback (most recent call last):
[Thu Apr 11 14:15:58.058040 2019] [wsgi:error] [pid 17744:tid 139660600817408] [remote 201.116.230.90:57411]   File "/home/kibblerz/pyenv/pyenv/lib/python3.5/site-packages/django/core/handlers/exception.py", line 34, in inner
[Thu Apr 11 14:15:58.058049 2019] [wsgi:error] [pid 17744:tid 139660600817408] [remote 201.116.230.90:57411]     response = get_response(request)
[Thu Apr 11 14:15:58.058061 2019] [wsgi:error] [pid 17744:tid 139660600817408] [remote 201.116.230.90:57411]   File "/home/kibblerz/pyenv/pyenv/lib/python3.5/site-packages/django/utils/deprecation.py", line 93, in __call__
[Thu Apr 11 14:15:58.058068 2019] [wsgi:error] [pid 17744:tid 139660600817408] [remote 201.116.230.90:57411]     response = self.process_request(request)
[Thu Apr 11 14:15:58.058079 2019] [wsgi:error] [pid 17744:tid 139660600817408] [remote 201.116.230.90:57411]   File "/home/kibblerz/pyenv/pyenv/lib/python3.5/site-packages/django/middleware/common.py", line 47, in process_request
[Thu Apr 11 14:15:58.058098 2019] [wsgi:error] [pid 17744:tid 139660600817408] [remote 201.116.230.90:57411]     host = request.get_host()
[Thu Apr 11 14:15:58.058110 2019] [wsgi:error] [pid 17744:tid 139660600817408] [remote 201.116.230.90:57411]   File "/home/kibblerz/pyenv/pyenv/lib/python3.5/site-packages/django/http/request.py", line 111, in get_host
[Thu Apr 11 14:15:58.058117 2019] [wsgi:error] [pid 17744:tid 139660600817408] [remote 201.116.230.90:57411]     raise DisallowedHost(msg)
[Thu Apr 11 14:15:58.058140 2019] [wsgi:error] [pid 17744:tid 139660600817408] [remote 201.116.230.90:57411] django.core.exceptions.DisallowedHost: Invalid HTTP_HOST header: 's97-74-233-104.secureserver.net'. You may need to add 's97-74-233-104.secureserver.net' to ALLOWED_HOSTS.
[Thu Apr 11 14:15:58.058156 2019] [wsgi:error] [pid 17744:tid 139660600817408] [remote 201.116.230.90:57411] 
[Thu Apr 11 14:15:58.058163 2019] [wsgi:error] [pid 17744:tid 139660600817408] [remote 201.116.230.90:57411] During handling of the above exception, another exception occurred:
[Thu Apr 11 14:15:58.058168 2019] [wsgi:error] [pid 17744:tid 139660600817408] [remote 201.116.230.90:57411] 
[Thu Apr 11 14:15:58.058179 2019] [wsgi:error] [pid 17744:tid 139660600817408] [remote 201.116.230.90:57411] Traceback (most recent call last):
[Thu Apr 11 14:15:58.058233 2019] [wsgi:error] [pid 17744:tid 139660600817408] [remote 201.116.230.90:57411]   File "/home/kibblerz/pyenv/pyenv/lib/python3.5/site-packages/django/core/handlers/exception.py", line 34, in inner
[Thu Apr 11 14:15:58.058241 2019] [wsgi:error] [pid 17744:tid 139660600817408] [remote 201.116.230.90:57411]     response = get_response(request)
[Thu Apr 11 14:15:58.058252 2019] [wsgi:error] [pid 17744:tid 139660600817408] [remote 201.116.230.90:57411]   File "/home/kibblerz/pyenv/pyenv/lib/python3.5/site-packages/django/utils/deprecation.py", line 94, in __call__
[Thu Apr 11 14:15:58.058259 2019] [wsgi:error] [pid 17744:tid 139660600817408] [remote 201.116.230.90:57411]     response = response or self.get_response(request)
[Thu Apr 11 14:15:58.058269 2019] [wsgi:error] [pid 17744:tid 139660600817408] [remote 201.116.230.90:57411]   File "/home/kibblerz/pyenv/pyenv/lib/python3.5/site-packages/django/core/handlers/exception.py", line 36, in inner
[Thu Apr 11 14:15:58.058275 2019] [wsgi:error] [pid 17744:tid 139660600817408] [remote 201.116.230.90:57411]     response = response_for_exception(request, exc)
[Thu Apr 11 14:15:58.058286 2019] [wsgi:error] [pid 17744:tid 139660600817408] [remote 201.116.230.90:57411]   File "/home/kibblerz/pyenv/pyenv/lib/python3.5/site-packages/django/core/handlers/exception.py", line 80, in response_for_exception
[Thu Apr 11 14:15:58.058293 2019] [wsgi:error] [pid 17744:tid 139660600817408] [remote 201.116.230.90:57411]     response = debug.technical_500_response(request, *sys.exc_info(), status_code=400)
[Thu Apr 11 14:15:58.058304 2019] [wsgi:error] [pid 17744:tid 139660600817408] [remote 201.116.230.90:57411]   File "/home/kibblerz/pyenv/pyenv/lib/python3.5/site-packages/django/views/debug.py", line 94, in technical_500_response
[Thu Apr 11 14:15:58.058311 2019] [wsgi:error] [pid 17744:tid 139660600817408] [remote 201.116.230.90:57411]     html = reporter.get_traceback_html()
[Thu Apr 11 14:15:58.058321 2019] [wsgi:error] [pid 17744:tid 139660600817408] [remote 201.116.230.90:57411]   File "/home/kibblerz/pyenv/pyenv/lib/python3.5/site-packages/django/views/debug.py", line 332, in get_traceback_html
[Thu Apr 11 14:15:58.058327 2019] [wsgi:error] [pid 17744:tid 139660600817408] [remote 201.116.230.90:57411]     t = DEBUG_ENGINE.from_string(fh.read())
[Thu Apr 11 14:15:58.058338 2019] [wsgi:error] [pid 17744:tid 139660600817408] [remote 201.116.230.90:57411]   File "/home/kibblerz/pyenv/pyenv/lib/python3.5/encodings/ascii.py", line 26, in decode
[Thu Apr 11 14:15:58.058344 2019] [wsgi:error] [pid 17744:tid 139660600817408] [remote 201.116.230.90:57411]     return codecs.ascii_decode(input, self.errors)[0]
[Thu Apr 11 14:15:58.058362 2019] [wsgi:error] [pid 17744:tid 139660600817408] [remote 201.116.230.90:57411] UnicodeDecodeError: 'ascii' codec can't decode byte 0xe2 in position 9735: ordinal not in range(128)
[Thu Apr 11 14:15:58.058382 2019] [wsgi:error] [pid 17744:tid 139660600817408] [remote 201.116.230.90:57411] 
[Thu Apr 11 14:15:58.058389 2019] [wsgi:error] [pid 17744:tid 139660600817408] [remote 201.116.230.90:57411] During handling of the above exception, another exception occurred:
[Thu Apr 11 14:15:58.058394 2019] [wsgi:error] [pid 17744:tid 139660600817408] [remote 201.116.230.90:57411] 
[Thu Apr 11 14:15:58.058405 2019] [wsgi:error] [pid 17744:tid 139660600817408] [remote 201.116.230.90:57411] Traceback (most recent call last):
[Thu Apr 11 14:15:58.058447 2019] [wsgi:error] [pid 17744:tid 139660600817408] [remote 201.116.230.90:57411]   File "/home/kibblerz/pyenv/pyenv/lib/python3.5/site-packages/django/core/handlers/exception.py", line 34, in inner
[Thu Apr 11 14:15:58.058455 2019] [wsgi:error] [pid 17744:tid 139660600817408] [remote 201.116.230.90:57411]     response = get_response(request)
[Thu Apr 11 14:15:58.058466 2019] [wsgi:error] [pid 17744:tid 139660600817408] [remote 201.116.230.90:57411]   File "/home/kibblerz/pyenv/pyenv/lib/python3.5/site-packages/django/utils/deprecation.py", line 94, in __call__
[Thu Apr 11 14:15:58.058473 2019] [wsgi:error] [pid 17744:tid 139660600817408] [remote 201.116.230.90:57411]     response = response or self.get_response(request)
[Thu Apr 11 14:15:58.058483 2019] [wsgi:error] [pid 17744:tid 139660600817408] [remote 201.116.230.90:57411]   File "/home/kibblerz/pyenv/pyenv/lib/python3.5/site-packages/django/core/handlers/exception.py", line 36, in inner
[Thu Apr 11 14:15:58.058489 2019] [wsgi:error] [pid 17744:tid 139660600817408] [remote 201.116.230.90:57411]     response = response_for_exception(request, exc)
[Thu Apr 11 14:15:58.058500 2019] [wsgi:error] [pid 17744:tid 139660600817408] [remote 201.116.230.90:57411]   File "/home/kibblerz/pyenv/pyenv/lib/python3.5/site-packages/django/core/handlers/exception.py", line 90, in response_for_exception
[Thu Apr 11 14:15:58.058506 2019] [wsgi:error] [pid 17744:tid 139660600817408] [remote 201.116.230.90:57411]     response = handle_uncaught_exception(request, get_resolver(get_urlconf()), sys.exc_info())
[Thu Apr 11 14:15:58.058517 2019] [wsgi:error] [pid 17744:tid 139660600817408] [remote 201.116.230.90:57411]   File "/home/kibblerz/pyenv/pyenv/lib/python3.5/site-packages/django/core/handlers/exception.py", line 125, in handle_uncaught_exception
[Thu Apr 11 14:15:58.058524 2019] [wsgi:error] [pid 17744:tid 139660600817408] [remote 201.116.230.90:57411]     return debug.technical_500_response(request, *exc_info)
[Thu Apr 11 14:15:58.058548 2019] [wsgi:error] [pid 17744:tid 139660600817408] [remote 201.116.230.90:57411]   File "/home/kibblerz/pyenv/pyenv/lib/python3.5/site-packages/django/views/debug.py", line 94, in technical_500_response
[Thu Apr 11 14:15:58.058555 2019] [wsgi:error] [pid 17744:tid 139660600817408] [remote 201.116.230.90:57411]     html = reporter.get_traceback_html()
[Thu Apr 11 14:15:58.058566 2019] [wsgi:error] [pid 17744:tid 139660600817408] [remote 201.116.230.90:57411]   File "/home/kibblerz/pyenv/pyenv/lib/python3.5/site-packages/django/views/debug.py", line 332, in get_traceback_html
[Thu Apr 11 14:15:58.058573 2019] [wsgi:error] [pid 17744:tid 139660600817408] [remote 201.116.230.90:57411]     t = DEBUG_ENGINE.from_string(fh.read())
[Thu Apr 11 14:15:58.058583 2019] [wsgi:error] [pid 17744:tid 139660600817408] [remote 201.116.230.90:57411]   File "/home/kibblerz/pyenv/pyenv/lib/python3.5/encodings/ascii.py", line 26, in decode
[Thu Apr 11 14:15:58.058590 2019] [wsgi:error] [pid 17744:tid 139660600817408] [remote 201.116.230.90:57411]     return codecs.ascii_decode(input, self.errors)[0]
[Thu Apr 11 14:15:58.058608 2019] [wsgi:error] [pid 17744:tid 139660600817408] [remote 201.116.230.90:57411] UnicodeDecodeError: 'ascii' codec can't decode byte 0xe2 in position 9735: ordinal not in range(128)
[Thu Apr 11 14:15:58.058623 2019] [wsgi:error] [pid 17744:tid 139660600817408] [remote 201.116.230.90:57411] 
[Thu Apr 11 14:15:58.058639 2019] [wsgi:error] [pid 17744:tid 139660600817408] [remote 201.116.230.90:57411] During handling of the above exception, another exception occurred:
[Thu Apr 11 14:15:58.058658 2019] [wsgi:error] [pid 17744:tid 139660600817408] [remote 201.116.230.90:57411] 
[Thu Apr 11 14:15:58.058670 2019] [wsgi:error] [pid 17744:tid 139660600817408] [remote 201.116.230.90:57411] Traceback (most recent call last):
[Thu Apr 11 14:15:58.058712 2019] [wsgi:error] [pid 17744:tid 139660600817408] [remote 201.116.230.90:57411]   File "/home/kibblerz/pyenv/pyenv/lib/python3.5/site-packages/django/core/handlers/wsgi.py", line 141, in __call__
[Thu Apr 11 14:15:58.058721 2019] [wsgi:error] [pid 17744:tid 139660600817408] [remote 201.116.230.90:57411]     response = self.get_response(request)
[Thu Apr 11 14:15:58.058732 2019] [wsgi:error] [pid 17744:tid 139660600817408] [remote 201.116.230.90:57411]   File "/home/kibblerz/pyenv/pyenv/lib/python3.5/site-packages/django/core/handlers/base.py", line 75, in get_response
[Thu Apr 11 14:15:58.058739 2019] [wsgi:error] [pid 17744:tid 139660600817408] [remote 201.116.230.90:57411]     response = self._middleware_chain(request)
[Thu Apr 11 14:15:58.058749 2019] [wsgi:error] [pid 17744:tid 139660600817408] [remote 201.116.230.90:57411]   File "/home/kibblerz/pyenv/pyenv/lib/python3.5/site-packages/django/core/handlers/exception.py", line 36, in inner
[Thu Apr 11 14:15:58.058756 2019] [wsgi:error] [pid 17744:tid 139660600817408] [remote 201.116.230.90:57411]     response = response_for_exception(request, exc)
[Thu Apr 11 14:15:58.058766 2019] [wsgi:error] [pid 17744:tid 139660600817408] [remote 201.116.230.90:57411]   File "/home/kibblerz/pyenv/pyenv/lib/python3.5/site-packages/django/core/handlers/exception.py", line 90, in response_for_exception
[Thu Apr 11 14:15:58.058773 2019] [wsgi:error] [pid 17744:tid 139660600817408] [remote 201.116.230.90:57411]     response = handle_uncaught_exception(request, get_resolver(get_urlconf()), sys.exc_info())
[Thu Apr 11 14:15:58.058784 2019] [wsgi:error] [pid 17744:tid 139660600817408] [remote 201.116.230.90:57411]   File "/home/kibblerz/pyenv/pyenv/lib/python3.5/site-packages/django/core/handlers/exception.py", line 125, in handle_uncaught_exception
[Thu Apr 11 14:15:58.058790 2019] [wsgi:error] [pid 17744:tid 139660600817408] [remote 201.116.230.90:57411]     return debug.technical_500_response(request, *exc_info)
[Thu Apr 11 14:15:58.058801 2019] [wsgi:error] [pid 17744:tid 139660600817408] [remote 201.116.230.90:57411]   File "/home/kibblerz/pyenv/pyenv/lib/python3.5/site-packages/django/views/debug.py", line 94, in technical_500_response
[Thu Apr 11 14:15:58.058808 2019] [wsgi:error] [pid 17744:tid 139660600817408] [remote 201.116.230.90:57411]     html = reporter.get_traceback_html()
[Thu Apr 11 14:15:58.058818 2019] [wsgi:error] [pid 17744:tid 139660600817408] [remote 201.116.230.90:57411]   File "/home/kibblerz/pyenv/pyenv/lib/python3.5/site-packages/django/views/debug.py", line 332, in get_traceback_html
[Thu Apr 11 14:15:58.058825 2019] [wsgi:error] [pid 17744:tid 139660600817408] [remote 201.116.230.90:57411]     t = DEBUG_ENGINE.from_string(fh.read())
[Thu Apr 11 14:15:58.058835 2019] [wsgi:error] [pid 17744:tid 139660600817408] [remote 201.116.230.90:57411]   File "/home/kibblerz/pyenv/pyenv/lib/python3.5/encodings/ascii.py", line 26, in decode
[Thu Apr 11 14:15:58.058841 2019] [wsgi:error] [pid 17744:tid 139660600817408] [remote 201.116.230.90:57411]     return codecs.ascii_decode(input, self.errors)[0]
[Thu Apr 11 14:15:58.058858 2019] [wsgi:error] [pid 17744:tid 139660600817408] [remote 201.116.230.90:57411] UnicodeDecodeError: 'ascii' codec can't decode byte 0xe2 in position 9735: ordinal not in range(128)
